"C:\Program Files (x86)\JetBrains\PyCharm 2016.1.4\bin\runnerw.exe" C:\Python27\python.exe C:/Users/diego/OneDrive/Projetos/sistema_contabil/manage.py runserver localhost:8000
Performing system checks...

System check identified no issues (0 silenced).
September 22, 2016 - 01:39:23
Django version 1.9.7, using settings 'sistema_contabil.settings'
Starting development server at http://localhost:8000/
Quit the server with CTRL-BREAK.
[22/Sep/2016 01:39:56] "GET / HTTP/1.1" 200 14418
Not Found: /favicon.ico
Not Found: /favicon.ico
[22/Sep/2016 01:39:59] "GET /favicon.ico HTTP/1.1" 404 4528
[22/Sep/2016 01:40:42] "GET / HTTP/1.1" 200 14418
[22/Sep/2016 01:42:51] "GET /entidade/cadastro HTTP/1.1" 301 0
[22/Sep/2016 01:42:52] "GET /entidade/cadastro/ HTTP/1.1" 200 40928
[22/Sep/2016 01:42:58] "GET /arquivos_estaticos/datatable/DataTables-1.10.11/css/dataTables.bootstrap.min.css HTTP/1.1" 200 4247
[22/Sep/2016 01:42:59] "GET /arquivos_estaticos/jquery/jquery-ui-1.11.4/jquery-ui.css HTTP/1.1" 200 34459
[22/Sep/2016 01:42:59] "GET /arquivos_estaticos/datatable/plugins/select/Select-1.1.2/css/select.bootstrap.min.css HTTP/1.1" 200 3890
[22/Sep/2016 01:42:59] "GET /arquivos_estaticos/datatable/plugins/responsivo/Responsive-2.0.2/css/responsive.bootstrap.min.css HTTP/1.1" 200 3886
[22/Sep/2016 01:42:59] "GET /arquivos_estaticos/datatable/DataTables-1.10.11/js/dataTables.bootstrap.min.js HTTP/1.1" 200 1960
[22/Sep/2016 01:42:59] "GET /arquivos_estaticos/datatable/plugins/select/Select-1.1.2/js/dataTables.select.min.js HTTP/1.1" 200 10731
[22/Sep/2016 01:42:59] "GET /arquivos_estaticos/datatable/datatables/media/js/jquery.dataTables.min.js HTTP/1.1" 404 1799
[22/Sep/2016 01:42:59] "GET /arquivos_estaticos/scripts/mask.js HTTP/1.1" 200 3568
[22/Sep/2016 01:42:59] "GET /arquivos_estaticos/datatable/DataTables-1.10.11/js/jquery.dataTables.min.js HTTP/1.1" 200 82480
[22/Sep/2016 01:42:59] "GET /arquivos_estaticos/datatable/datatables-plugins/integration/bootstrap/3/dataTables.bootstrap.min.js HTTP/1.1" 404 1877
[22/Sep/2016 01:43:00] "GET /arquivos_estaticos/bootstrap/fonts/glyphicons-halflings-regular.woff2 HTTP/1.1" 200 18028
[22/Sep/2016 01:43:00] "GET /arquivos_estaticos/datatable/datatables/media/js/jquery.dataTables.min.js HTTP/1.1" 404 1799
[22/Sep/2016 01:43:01] "GET /arquivos_estaticos/datatable/datatables-plugins/integration/bootstrap/3/dataTables.bootstrap.min.js HTTP/1.1" 404 1877
Performing system checks...

System check identified no issues (0 silenced).
September 22, 2016 - 01:51:45
Django version 1.9.7, using settings 'sistema_contabil.settings'
Starting development server at http://localhost:8000/
Quit the server with CTRL-BREAK.
[22/Sep/2016 01:53:54] "GET /entidade/visualizar/2 HTTP/1.1" 301 0
[22/Sep/2016 01:53:55] "GET /entidade/visualizar/2/ HTTP/1.1" 200 65423
[22/Sep/2016 01:54:02] "GET /arquivos_estaticos/jquery/jquery-editable-select/jquery.editable-select.min.css HTTP/1.1" 200 1160
[22/Sep/2016 01:54:02] "GET /arquivos_estaticos/scripts/protocolo/protocolo.js HTTP/1.1" 200 2620
[22/Sep/2016 01:54:02] "GET /arquivos_estaticos/scripts/padrao/controle_botoes.js HTTP/1.1" 200 159
[22/Sep/2016 01:54:02] "GET /arquivos_estaticos/jquery/jquery-editable-select/jquery.editable-select.min.js HTTP/1.1" 200 3386
[22/Sep/2016 01:54:02] "GET /arquivos_estaticos/angular-1.5.8/angular.min.js HTTP/1.1" 200 160366
carregando..
VALIDANDO A LOCALIZACAO: (True, '')
carregando..
VALIDANDO A ENTIDADE: (True, '')
Internal Server Error: /entidade/visualizar/2/
Traceback (most recent call last):
  File "C:\Python27\lib\site-packages\django\core\handlers\base.py", line 149, in get_response
    response = self.process_exception_by_middleware(e, request)
  File "C:\Python27\lib\site-packages\django\core\handlers\base.py", line 147, in get_response
    response = wrapped_callback(request, *callback_args, **callback_kwargs)
  File "C:\Users\diego\OneDrive\Projetos\sistema_contabil\entidade\views.py", line 512, in visualizar_entidade
    lista_objetos = load_objects_from_form(formulario,cliente,cliente.endereco,meus_contatos,minhas_atividades)
  File "C:\Users\diego\OneDrive\Projetos\sistema_contabil\entidade\views.py", line 639, in load_objects_from_form
    registro_contatos = formulario.get_contatos(formulario, cliente)
TypeError: get_object_contatos() takes exactly 4 arguments (3 given)
Internal Server Error: /entidade/visualizar/2/
Traceback (most recent call last):
  File "C:\Python27\lib\site-packages\django\core\handlers\base.py", line 149, in get_response
    response = self.process_exception_by_middleware(e, request)
  File "C:\Python27\lib\site-packages\django\core\handlers\base.py", line 147, in get_response
    response = wrapped_callback(request, *callback_args, **callback_kwargs)
  File "C:\Users\diego\OneDrive\Projetos\sistema_contabil\entidade\views.py", line 512, in visualizar_entidade
    lista_objetos = load_objects_from_form(formulario,cliente,cliente.endereco,meus_contatos,minhas_atividades)
  File "C:\Users\diego\OneDrive\Projetos\sistema_contabil\entidade\views.py", line 639, in load_objects_from_form
    registro_contatos = formulario.get_contatos(formulario, cliente)
TypeError: get_object_contatos() takes exactly 4 arguments (3 given)
[22/Sep/2016 02:00:27] "POST /entidade/visualizar/2/ HTTP/1.1" 500 75064
Performing system checks...

System check identified no issues (0 silenced).
September 22, 2016 - 02:08:37
Django version 1.9.7, using settings 'sistema_contabil.settings'
Starting development server at http://localhost:8000/
Quit the server with CTRL-BREAK.
carregando..
VALIDANDO A LOCALIZACAO: (True, '')
carregando..
VALIDANDO A ENTIDADE: (True, '')
Internal Server Error: /entidade/visualizar/2/
Traceback (most recent call last):
  File "C:\Python27\lib\site-packages\django\core\handlers\base.py", line 149, in get_response
    response = self.process_exception_by_middleware(e, request)
  File "C:\Python27\lib\site-packages\django\core\handlers\base.py", line 147, in get_response
    response = wrapped_callback(request, *callback_args, **callback_kwargs)
  File "C:\Users\diego\OneDrive\Projetos\sistema_contabil\entidade\views.py", line 512, in visualizar_entidade
    lista_objetos = load_objects_from_form(formulario,cliente,cliente.endereco,meus_contatos,minhas_atividades)
  File "C:\Users\diego\OneDrive\Projetos\sistema_contabil\entidade\views.py", line 639, in load_objects_from_form
    registro_contatos = formulario.get_contatos(formulario, cliente)
  File "C:\Users\diego\OneDrive\Projetos\sistema_contabil\entidade\formularios.py", line 150, in get_object_contatos
    email = dados[4]
IndexError: list index out of range
Internal Server Error: /entidade/visualizar/2/
Traceback (most recent call last):
  File "C:\Python27\lib\site-packages\django\core\handlers\base.py", line 149, in get_response
    response = self.process_exception_by_middleware(e, request)
  File "C:\Python27\lib\site-packages\django\core\handlers\base.py", line 147, in get_response
    response = wrapped_callback(request, *callback_args, **callback_kwargs)
  File "C:\Users\diego\OneDrive\Projetos\sistema_contabil\entidade\views.py", line 512, in visualizar_entidade
    lista_objetos = load_objects_from_form(formulario,cliente,cliente.endereco,meus_contatos,minhas_atividades)
  File "C:\Users\diego\OneDrive\Projetos\sistema_contabil\entidade\views.py", line 639, in load_objects_from_form
    registro_contatos = formulario.get_contatos(formulario, cliente)
  File "C:\Users\diego\OneDrive\Projetos\sistema_contabil\entidade\formularios.py", line 150, in get_object_contatos
    email = dados[4]
IndexError: list index out of range
[22/Sep/2016 02:08:44] "POST /entidade/visualizar/2/ HTTP/1.1" 500 81087
Performing system checks...

System check identified no issues (0 silenced).
September 22, 2016 - 02:09:31
Django version 1.9.7, using settings 'sistema_contabil.settings'
Starting development server at http://localhost:8000/
Quit the server with CTRL-BREAK.
carregando..
VALIDANDO A LOCALIZACAO: (True, '')
carregando..
VALIDANDO A ENTIDADE: (True, '')
OLHA OS CAMPOS NA HORA DE CONSTRUIR O CONTATO: [u'CELULAR', u'(22) 222222222', u'DIEGO PASTI', u'PARTICULAR', u'']
OLHA OS CAMPOS NA HORA DE CONSTRUIR O CONTATO: [u'CELULAR', u'(27) 999881254', u'DIEGO PASTI', u'PARTICULAR', u'diegopasti@gmail.com']
OLHA OS CAMPOS NA HORA DE CONSTRUIR O CONTATO: [u'RESIDENCIAL', u'(27) 3043-0703', u'', u'']
Internal Server Error: /entidade/visualizar/2/
Traceback (most recent call last):
  File "C:\Python27\lib\site-packages\django\core\handlers\base.py", line 149, in get_response
    response = self.process_exception_by_middleware(e, request)
  File "C:\Python27\lib\site-packages\django\core\handlers\base.py", line 147, in get_response
    response = wrapped_callback(request, *callback_args, **callback_kwargs)
  File "C:\Users\diego\OneDrive\Projetos\sistema_contabil\entidade\views.py", line 512, in visualizar_entidade
    lista_objetos = load_objects_from_form(formulario,cliente,cliente.endereco,meus_contatos,minhas_atividades)
  File "C:\Users\diego\OneDrive\Projetos\sistema_contabil\entidade\views.py", line 639, in load_objects_from_form
    registro_contatos = formulario.get_contatos(formulario, cliente)
  File "C:\Users\diego\OneDrive\Projetos\sistema_contabil\entidade\formularios.py", line 150, in get_object_contatos
    email = dados[4]
IndexError: list index out of range
Internal Server Error: /entidade/visualizar/2/
Traceback (most recent call last):
  File "C:\Python27\lib\site-packages\django\core\handlers\base.py", line 149, in get_response
    response = self.process_exception_by_middleware(e, request)
  File "C:\Python27\lib\site-packages\django\core\handlers\base.py", line 147, in get_response
    response = wrapped_callback(request, *callback_args, **callback_kwargs)
  File "C:\Users\diego\OneDrive\Projetos\sistema_contabil\entidade\views.py", line 512, in visualizar_entidade
    lista_objetos = load_objects_from_form(formulario,cliente,cliente.endereco,meus_contatos,minhas_atividades)
  File "C:\Users\diego\OneDrive\Projetos\sistema_contabil\entidade\views.py", line 639, in load_objects_from_form
    registro_contatos = formulario.get_contatos(formulario, cliente)
  File "C:\Users\diego\OneDrive\Projetos\sistema_contabil\entidade\formularios.py", line 150, in get_object_contatos
    email = dados[4]
IndexError: list index out of range
[22/Sep/2016 02:10:00] "POST /entidade/visualizar/2/ HTTP/1.1" 500 81086
[22/Sep/2016 02:26:20] "GET /entidade/visualizar/2/ HTTP/1.1" 200 65423
carregando..
VALIDANDO A LOCALIZACAO: (True, '')
carregando..
VALIDANDO A ENTIDADE: (True, '')
OLHA OS CAMPOS NA HORA DE CONSTRUIR O CONTATO: [u'CELULAR', u'(22) 222222222', u'DIEGO PASTI', u'PARTICULAR', u'']
OLHA OS CAMPOS NA HORA DE CONSTRUIR O CONTATO: [u'CELULAR', u'(27) 999881254', u'DIEGO PASTI', u'PARTICULAR', u'diegopasti@gmail.com']
OLHA OS CAMPOS NA HORA DE CONSTRUIR O CONTATO: [u'RESIDENCIAL', u'(27) 3043-0703', u'', u'']
Internal Server Error: /entidade/visualizar/2/
Traceback (most recent call last):
  File "C:\Python27\lib\site-packages\django\core\handlers\base.py", line 149, in get_response
    response = self.process_exception_by_middleware(e, request)
  File "C:\Python27\lib\site-packages\django\core\handlers\base.py", line 147, in get_response
    response = wrapped_callback(request, *callback_args, **callback_kwargs)
  File "C:\Users\diego\OneDrive\Projetos\sistema_contabil\entidade\views.py", line 512, in visualizar_entidade
    lista_objetos = load_objects_from_form(formulario,cliente,cliente.endereco,meus_contatos,minhas_atividades)
  File "C:\Users\diego\OneDrive\Projetos\sistema_contabil\entidade\views.py", line 639, in load_objects_from_form
    registro_contatos = formulario.get_contatos(formulario, cliente)
  File "C:\Users\diego\OneDrive\Projetos\sistema_contabil\entidade\formularios.py", line 150, in get_object_contatos
    email = dados[4]
IndexError: list index out of range
Internal Server Error: /entidade/visualizar/2/
Traceback (most recent call last):
  File "C:\Python27\lib\site-packages\django\core\handlers\base.py", line 149, in get_response
    response = self.process_exception_by_middleware(e, request)
  File "C:\Python27\lib\site-packages\django\core\handlers\base.py", line 147, in get_response
    response = wrapped_callback(request, *callback_args, **callback_kwargs)
  File "C:\Users\diego\OneDrive\Projetos\sistema_contabil\entidade\views.py", line 512, in visualizar_entidade
    lista_objetos = load_objects_from_form(formulario,cliente,cliente.endereco,meus_contatos,minhas_atividades)
  File "C:\Users\diego\OneDrive\Projetos\sistema_contabil\entidade\views.py", line 639, in load_objects_from_form
    registro_contatos = formulario.get_contatos(formulario, cliente)
  File "C:\Users\diego\OneDrive\Projetos\sistema_contabil\entidade\formularios.py", line 150, in get_object_contatos
    email = dados[4]
IndexError: list index out of range
[22/Sep/2016 02:59:42] "POST /entidade/visualizar/2/ HTTP/1.1" 500 81086
[22/Sep/2016 03:00:14] "GET /entidade/visualizar/2/ HTTP/1.1" 200 65438
[22/Sep/2016 03:08:08] "GET /entidade/visualizar/2/ HTTP/1.1" 200 65439
carregando..
VALIDANDO A LOCALIZACAO: (True, '')
carregando..
VALIDANDO A ENTIDADE: (True, '')
OLHA OS CAMPOS NA HORA DE CONSTRUIR O CONTATO: [u'CELULAR', u'(22) 222222222', u'DIEGO PASTI', u'PARTICULAR', u'']
OLHA OS CAMPOS NA HORA DE CONSTRUIR O CONTATO: [u'CELULAR', u'(27) 999881254', u'DIEGO PASTI', u'PARTICULAR', u'diegopasti@gmail.com']
OLHA OS CAMPOS NA HORA DE CONSTRUIR O CONTATO: [u'COMERCIAL', u'(27) 3043-0703', u'', u'', u'']
VALIDANDO OS CONTATOS: (True, '')
Internal Server Error: /entidade/visualizar/2/
Traceback (most recent call last):
  File "C:\Python27\lib\site-packages\django\core\handlers\base.py", line 158, in get_response
    % (callback.__module__, view_name))
ValueError: The view entidade.views.visualizar_entidade didn't return an HttpResponse object. It returned None instead.
Internal Server Error: /entidade/visualizar/2/
Traceback (most recent call last):
  File "C:\Python27\lib\site-packages\django\core\handlers\base.py", line 158, in get_response
    % (callback.__module__, view_name))
ValueError: The view entidade.views.visualizar_entidade didn't return an HttpResponse object. It returned None instead.
[22/Sep/2016 03:08:54] "POST /entidade/visualizar/2/ HTTP/1.1" 500 58346
Performing system checks...

System check identified no issues (0 silenced).
September 22, 2016 - 03:52:44
Django version 1.9.7, using settings 'sistema_contabil.settings'
Starting development server at http://localhost:8000/
Quit the server with CTRL-BREAK.
[22/Sep/2016 03:58:04] "GET /entidade/visualizar/2/ HTTP/1.1" 200 65439
[22/Sep/2016 04:33:29] "GET /entidade/visualizar/2/ HTTP/1.1" 200 65439
Unhandled exception in thread started by <function wrapper at 0x0470FEF0>
Traceback (most recent call last):

Process finished with exit code 0
