"C:\Program Files (x86)\JetBrains\PyCharm 2016.1.4\bin\runnerw.exe" C:\Python27\python.exe C:/Users/diego/OneDrive/Projetos/sistema_contabil/manage.py runserver localhost:8000
Performing system checks...

System check identified no issues (0 silenced).
September 20, 2016 - 18:14:17
Django version 1.9.7, using settings 'sistema_contabil.settings'
Starting development server at http://localhost:8000/
Quit the server with CTRL-BREAK.
[20/Sep/2016 18:14:24] "GET / HTTP/1.1" 200 14418
Not Found: /favicon.ico
Not Found: /favicon.ico
[20/Sep/2016 18:14:26] "GET /favicon.ico HTTP/1.1" 404 4528
[20/Sep/2016 19:28:08] "GET /entidade/cadastro/ HTTP/1.1" 200 40928
[20/Sep/2016 19:28:08] "GET /arquivos_estaticos/datatable/datatables-plugins/integration/bootstrap/3/dataTables.bootstrap.min.js HTTP/1.1" 404 1877
[20/Sep/2016 19:28:09] "GET /arquivos_estaticos/datatable/datatables/media/js/jquery.dataTables.min.js HTTP/1.1" 404 1799
[20/Sep/2016 19:28:09] "GET /arquivos_estaticos/datatable/datatables/media/js/jquery.dataTables.min.js HTTP/1.1" 404 1799
[20/Sep/2016 19:28:10] "GET /arquivos_estaticos/datatable/datatables-plugins/integration/bootstrap/3/dataTables.bootstrap.min.js HTTP/1.1" 404 1877
[20/Sep/2016 19:28:35] "GET /entidade/adicionar/ HTTP/1.1" 200 351099
[20/Sep/2016 19:28:36] "GET /arquivos_estaticos/angular-1.5.8/angular.min.js HTTP/1.1" 304 0
Endereco:  29156700
[20/Sep/2016 19:30:17] "GET /entidade/visualizar/7/ HTTP/1.1" 200 64589
Performing system checks...

System check identified no issues (0 silenced).
September 20, 2016 - 19:34:20
Django version 1.9.7, using settings 'sistema_contabil.settings'
Starting development server at http://localhost:8000/
Quit the server with CTRL-BREAK.
Internal Server Error: /entidade/visualizar/7/
Traceback (most recent call last):
  File "C:\Python27\lib\site-packages\django\core\handlers\base.py", line 149, in get_response
    response = self.process_exception_by_middleware(e, request)
  File "C:\Python27\lib\site-packages\django\core\handlers\base.py", line 147, in get_response
    response = wrapped_callback(request, *callback_args, **callback_kwargs)
  File "C:\Users\diego\OneDrive\Projetos\sistema_contabil\entidade\views.py", line 522, in visualizar_entidade
    contatos = contato.objecs.filter(entidade=cliente)
AttributeError: type object 'contato' has no attribute 'objecs'
Internal Server Error: /entidade/visualizar/7/
Traceback (most recent call last):
  File "C:\Python27\lib\site-packages\django\core\handlers\base.py", line 149, in get_response
    response = self.process_exception_by_middleware(e, request)
  File "C:\Python27\lib\site-packages\django\core\handlers\base.py", line 147, in get_response
    response = wrapped_callback(request, *callback_args, **callback_kwargs)
  File "C:\Users\diego\OneDrive\Projetos\sistema_contabil\entidade\views.py", line 522, in visualizar_entidade
    contatos = contato.objecs.filter(entidade=cliente)
AttributeError: type object 'contato' has no attribute 'objecs'
[20/Sep/2016 19:36:27] "GET /entidade/visualizar/7/ HTTP/1.1" 500 63522
Performing system checks...

System check identified no issues (0 silenced).
September 20, 2016 - 19:37:05
Django version 1.9.7, using settings 'sistema_contabil.settings'
Starting development server at http://localhost:8000/
Quit the server with CTRL-BREAK.
olha os contatos desse cliente:
(27) 32843151
[20/Sep/2016 19:37:08] "GET /entidade/visualizar/7/ HTTP/1.1" 200 64589
[20/Sep/2016 19:37:08] "GET /arquivos_estaticos/jquery/jquery-2.2.0.min.js HTTP/1.1" 304 0
[20/Sep/2016 19:37:10] "GET /arquivos_estaticos/jquery/jquery-ui-1.11.4/jquery-ui.js HTTP/1.1" 304 0
[20/Sep/2016 19:37:10] "GET /arquivos_estaticos/bootstrap/css/bootstrap.min.css HTTP/1.1" 304 0
[20/Sep/2016 19:37:10] "GET /arquivos_estaticos/bootstrap/js/bootstrap.min.js HTTP/1.1" 304 0
[20/Sep/2016 19:37:11] "GET /arquivos_estaticos/icones/css/font-awesome.min.css HTTP/1.1" 304 0
[20/Sep/2016 19:37:11] "GET /arquivos_estaticos/adminlte/css/AdminLTE.min.css HTTP/1.1" 304 0
[20/Sep/2016 19:37:11] "GET /arquivos_estaticos/adminlte/css/skins/skin-blue.min.css HTTP/1.1" 304 0
[20/Sep/2016 19:37:11] "GET /arquivos_estaticos/datatable/DataTables-1.10.11/css/dataTables.bootstrap.min.css HTTP/1.1" 304 0
[20/Sep/2016 19:37:11] "GET /arquivos_estaticos/datatable/plugins/responsivo/Responsive-2.0.2/css/responsive.bootstrap.min.css HTTP/1.1" 304 0
[20/Sep/2016 19:37:11] "GET /arquivos_estaticos/datatable/plugins/select/Select-1.1.2/css/select.bootstrap.min.css HTTP/1.1" 304 0
[20/Sep/2016 19:37:11] "GET /arquivos_estaticos/datatable/DataTables-1.10.11/js/jquery.dataTables.min.js HTTP/1.1" 304 0
[20/Sep/2016 19:37:11] "GET /arquivos_estaticos/datatable/DataTables-1.10.11/js/dataTables.bootstrap.min.js HTTP/1.1" 304 0
[20/Sep/2016 19:37:11] "GET /arquivos_estaticos/datatable/plugins/select/Select-1.1.2/js/dataTables.select.min.js HTTP/1.1" 304 0
[20/Sep/2016 19:37:11] "GET /arquivos_estaticos/jquery/jquery-ui-1.11.4/jquery-ui.css HTTP/1.1" 304 0
[20/Sep/2016 19:37:11] "GET /arquivos_estaticos/jquery/jquery-editable-select/jquery.editable-select.min.css HTTP/1.1" 304 0
[20/Sep/2016 19:37:11] "GET /arquivos_estaticos/jquery/jquery-editable-select/jquery.editable-select.min.js HTTP/1.1" 304 0
[20/Sep/2016 19:37:11] "GET /arquivos_estaticos/scripts/padrao/controle_botoes.js HTTP/1.1" 304 0
[20/Sep/2016 19:37:11] "GET /arquivos_estaticos/scripts/protocolo/protocolo.js HTTP/1.1" 304 0
[20/Sep/2016 19:37:11] "GET /arquivos_estaticos/angular-1.5.8/angular.min.js HTTP/1.1" 304 0
[20/Sep/2016 19:37:11] "GET /arquivos_estaticos/adminlte/js/app.min.js HTTP/1.1" 304 0
[20/Sep/2016 19:37:11] "GET /arquivos_estaticos/scripts/mask.js HTTP/1.1" 304 0
[20/Sep/2016 19:37:12] "GET /arquivos_estaticos/imagens/logo.png HTTP/1.1" 304 0
[20/Sep/2016 19:37:12] "GET /arquivos_estaticos/imagens/avatar5.png HTTP/1.1" 304 0
Performing system checks...

System check identified no issues (0 silenced).
September 20, 2016 - 19:39:50
Django version 1.9.7, using settings 'sistema_contabil.settings'
Starting development server at http://localhost:8000/
Quit the server with CTRL-BREAK.
olha os contatos desse cliente: [<contato: (27) 32843151>]
[20/Sep/2016 20:01:09] "GET /entidade/visualizar/7/ HTTP/1.1" 200 65426
olha os contatos desse cliente: [<contato: (27) 32843151>]
[20/Sep/2016 20:01:42] "GET /entidade/visualizar/7/ HTTP/1.1" 200 65368
olha os contatos desse cliente: [<contato: (27) 32843151>]
[20/Sep/2016 20:02:00] "GET /entidade/visualizar/7/ HTTP/1.1" 200 65426
[20/Sep/2016 20:02:01] "GET /arquivos_estaticos/jquery/jquery-ui-1.11.4/jquery-ui.js HTTP/1.1" 304 0
[20/Sep/2016 20:02:01] "GET /arquivos_estaticos/jquery/jquery-2.2.0.min.js HTTP/1.1" 304 0
[20/Sep/2016 20:02:01] "GET /arquivos_estaticos/bootstrap/css/bootstrap.min.css HTTP/1.1" 304 0
[20/Sep/2016 20:02:01] "GET /arquivos_estaticos/bootstrap/js/bootstrap.min.js HTTP/1.1" 304 0
[20/Sep/2016 20:02:01] "GET /arquivos_estaticos/icones/css/font-awesome.min.css HTTP/1.1" 304 0
[20/Sep/2016 20:02:01] "GET /arquivos_estaticos/adminlte/css/AdminLTE.min.css HTTP/1.1" 304 0
[20/Sep/2016 20:02:01] "GET /arquivos_estaticos/adminlte/css/skins/skin-blue.min.css HTTP/1.1" 304 0
[20/Sep/2016 20:02:01] "GET /arquivos_estaticos/datatable/DataTables-1.10.11/css/dataTables.bootstrap.min.css HTTP/1.1" 304 0
[20/Sep/2016 20:02:01] "GET /arquivos_estaticos/datatable/plugins/responsivo/Responsive-2.0.2/css/responsive.bootstrap.min.css HTTP/1.1" 304 0
[20/Sep/2016 20:02:02] "GET /arquivos_estaticos/datatable/plugins/select/Select-1.1.2/css/select.bootstrap.min.css HTTP/1.1" 304 0
[20/Sep/2016 20:02:02] "GET /arquivos_estaticos/datatable/DataTables-1.10.11/js/jquery.dataTables.min.js HTTP/1.1" 304 0
[20/Sep/2016 20:02:02] "GET /arquivos_estaticos/datatable/DataTables-1.10.11/js/dataTables.bootstrap.min.js HTTP/1.1" 304 0
[20/Sep/2016 20:02:02] "GET /arquivos_estaticos/datatable/plugins/select/Select-1.1.2/js/dataTables.select.min.js HTTP/1.1" 304 0
[20/Sep/2016 20:02:02] "GET /arquivos_estaticos/jquery/jquery-ui-1.11.4/jquery-ui.css HTTP/1.1" 304 0
[20/Sep/2016 20:02:02] "GET /arquivos_estaticos/jquery/jquery-editable-select/jquery.editable-select.min.css HTTP/1.1" 304 0
[20/Sep/2016 20:02:02] "GET /arquivos_estaticos/jquery/jquery-editable-select/jquery.editable-select.min.js HTTP/1.1" 304 0
[20/Sep/2016 20:02:02] "GET /arquivos_estaticos/scripts/padrao/controle_botoes.js HTTP/1.1" 304 0
[20/Sep/2016 20:02:02] "GET /arquivos_estaticos/scripts/protocolo/protocolo.js HTTP/1.1" 304 0
[20/Sep/2016 20:02:02] "GET /arquivos_estaticos/angular-1.5.8/angular.min.js HTTP/1.1" 304 0
[20/Sep/2016 20:02:02] "GET /arquivos_estaticos/adminlte/js/app.min.js HTTP/1.1" 304 0
[20/Sep/2016 20:02:02] "GET /arquivos_estaticos/scripts/mask.js HTTP/1.1" 304 0
[20/Sep/2016 20:02:03] "GET /arquivos_estaticos/imagens/avatar5.png HTTP/1.1" 304 0
[20/Sep/2016 20:02:03] "GET /arquivos_estaticos/imagens/logo.png HTTP/1.1" 304 0
olha os contatos desse cliente: [<contato: (27) 32843151>]
[20/Sep/2016 20:11:02] "GET /entidade/visualizar/7/ HTTP/1.1" 200 66011
olha os contatos desse cliente: [<contato: (27) 32843151>]
[20/Sep/2016 20:14:09] "GET /entidade/visualizar/7/ HTTP/1.1" 200 66029
[20/Sep/2016 20:15:22] "GET /arquivos_estaticos/angular-1.5.8/angular.min.js.map HTTP/1.1" 404 1733
[20/Sep/2016 20:15:32] "GET /arquivos_estaticos/bootstrap/css/bootstrap.min.css.map HTTP/1.1" 200 54416
[20/Sep/2016 20:15:32] "GET /arquivos_estaticos/bootstrap/css/bootstrap.min.css.map HTTP/1.1" 200 54416
olha os contatos desse cliente: [<contato: (27) 32843151>]
[20/Sep/2016 20:16:07] "GET /entidade/visualizar/7/ HTTP/1.1" 200 66029
[20/Sep/2016 20:16:10] "GET /arquivos_estaticos/angular-1.5.8/angular.min.js.map HTTP/1.1" 404 1733
[20/Sep/2016 20:16:18] "GET /arquivos_estaticos/bootstrap/css/bootstrap.min.css.map HTTP/1.1" 200 54416
[20/Sep/2016 20:16:18] "GET /arquivos_estaticos/bootstrap/css/bootstrap.min.css.map HTTP/1.1" 200 54416
olha os contatos desse cliente: [<contato: (27) 32843151>]
[20/Sep/2016 20:17:13] "GET /entidade/visualizar/7/ HTTP/1.1" 200 66029
[20/Sep/2016 20:17:17] "GET /arquivos_estaticos/angular-1.5.8/angular.min.js.map HTTP/1.1" 404 1733
[20/Sep/2016 20:17:23] "GET /arquivos_estaticos/bootstrap/css/bootstrap.min.css.map HTTP/1.1" 200 54416
[20/Sep/2016 20:17:23] "GET /arquivos_estaticos/bootstrap/css/bootstrap.min.css.map HTTP/1.1" 200 54416
olha os contatos desse cliente: [<contato: (27) 32843151>]
[20/Sep/2016 20:23:21] "GET /entidade/visualizar/7/ HTTP/1.1" 200 66522
olha os contatos desse cliente: [<contato: (27) 32843151>]
[20/Sep/2016 20:24:10] "GET /entidade/visualizar/7/ HTTP/1.1" 200 66601
[20/Sep/2016 20:24:10] "GET /arquivos_estaticos/jquery/jquery-2.2.0.min.js HTTP/1.1" 304 0
[20/Sep/2016 20:24:10] "GET /arquivos_estaticos/jquery/jquery-ui-1.11.4/jquery-ui.js HTTP/1.1" 304 0
[20/Sep/2016 20:24:10] "GET /arquivos_estaticos/bootstrap/css/bootstrap.min.css HTTP/1.1" 304 0
[20/Sep/2016 20:24:10] "GET /arquivos_estaticos/bootstrap/js/bootstrap.min.js HTTP/1.1" 304 0
[20/Sep/2016 20:24:10] "GET /arquivos_estaticos/icones/css/font-awesome.min.css HTTP/1.1" 304 0
[20/Sep/2016 20:24:10] "GET /arquivos_estaticos/adminlte/css/AdminLTE.min.css HTTP/1.1" 304 0
[20/Sep/2016 20:24:10] "GET /arquivos_estaticos/adminlte/css/skins/skin-blue.min.css HTTP/1.1" 304 0
[20/Sep/2016 20:24:10] "GET /arquivos_estaticos/datatable/DataTables-1.10.11/css/dataTables.bootstrap.min.css HTTP/1.1" 304 0
[20/Sep/2016 20:24:10] "GET /arquivos_estaticos/datatable/plugins/responsivo/Responsive-2.0.2/css/responsive.bootstrap.min.css HTTP/1.1" 304 0
[20/Sep/2016 20:24:10] "GET /arquivos_estaticos/datatable/plugins/select/Select-1.1.2/css/select.bootstrap.min.css HTTP/1.1" 304 0
[20/Sep/2016 20:24:10] "GET /arquivos_estaticos/datatable/DataTables-1.10.11/js/jquery.dataTables.min.js HTTP/1.1" 304 0
[20/Sep/2016 20:24:10] "GET /arquivos_estaticos/datatable/DataTables-1.10.11/js/dataTables.bootstrap.min.js HTTP/1.1" 304 0
[20/Sep/2016 20:24:10] "GET /arquivos_estaticos/datatable/plugins/select/Select-1.1.2/js/dataTables.select.min.js HTTP/1.1" 304 0
[20/Sep/2016 20:24:10] "GET /arquivos_estaticos/jquery/jquery-ui-1.11.4/jquery-ui.css HTTP/1.1" 304 0
[20/Sep/2016 20:24:11] "GET /arquivos_estaticos/jquery/jquery-editable-select/jquery.editable-select.min.css HTTP/1.1" 304 0
[20/Sep/2016 20:24:11] "GET /arquivos_estaticos/jquery/jquery-editable-select/jquery.editable-select.min.js HTTP/1.1" 304 0
[20/Sep/2016 20:24:11] "GET /arquivos_estaticos/scripts/padrao/controle_botoes.js HTTP/1.1" 304 0
[20/Sep/2016 20:24:11] "GET /arquivos_estaticos/scripts/protocolo/protocolo.js HTTP/1.1" 304 0
[20/Sep/2016 20:24:11] "GET /arquivos_estaticos/angular-1.5.8/angular.min.js HTTP/1.1" 304 0
[20/Sep/2016 20:24:11] "GET /arquivos_estaticos/adminlte/js/app.min.js HTTP/1.1" 304 0
[20/Sep/2016 20:24:11] "GET /arquivos_estaticos/scripts/mask.js HTTP/1.1" 304 0
[20/Sep/2016 20:24:12] "GET /arquivos_estaticos/imagens/logo.png HTTP/1.1" 304 0
[20/Sep/2016 20:24:12] "GET /arquivos_estaticos/imagens/avatar5.png HTTP/1.1" 304 0
olha os contatos desse cliente: [<contato: (27) 32843151>]
[20/Sep/2016 20:24:21] "GET /entidade/visualizar/7/ HTTP/1.1" 200 66600
[20/Sep/2016 20:24:22] "GET /arquivos_estaticos/jquery/jquery-2.2.0.min.js HTTP/1.1" 304 0
[20/Sep/2016 20:24:22] "GET /arquivos_estaticos/jquery/jquery-ui-1.11.4/jquery-ui.js HTTP/1.1" 304 0
[20/Sep/2016 20:24:22] "GET /arquivos_estaticos/bootstrap/css/bootstrap.min.css HTTP/1.1" 304 0
[20/Sep/2016 20:24:22] "GET /arquivos_estaticos/bootstrap/js/bootstrap.min.js HTTP/1.1" 304 0
[20/Sep/2016 20:24:22] "GET /arquivos_estaticos/icones/css/font-awesome.min.css HTTP/1.1" 304 0
[20/Sep/2016 20:24:22] "GET /arquivos_estaticos/adminlte/css/AdminLTE.min.css HTTP/1.1" 304 0
[20/Sep/2016 20:24:22] "GET /arquivos_estaticos/adminlte/css/skins/skin-blue.min.css HTTP/1.1" 304 0
[20/Sep/2016 20:24:22] "GET /arquivos_estaticos/datatable/DataTables-1.10.11/css/dataTables.bootstrap.min.css HTTP/1.1" 304 0
[20/Sep/2016 20:24:22] "GET /arquivos_estaticos/datatable/plugins/responsivo/Responsive-2.0.2/css/responsive.bootstrap.min.css HTTP/1.1" 304 0
[20/Sep/2016 20:24:23] "GET /arquivos_estaticos/datatable/plugins/select/Select-1.1.2/css/select.bootstrap.min.css HTTP/1.1" 304 0
[20/Sep/2016 20:24:23] "GET /arquivos_estaticos/datatable/DataTables-1.10.11/js/jquery.dataTables.min.js HTTP/1.1" 304 0
[20/Sep/2016 20:24:23] "GET /arquivos_estaticos/datatable/DataTables-1.10.11/js/dataTables.bootstrap.min.js HTTP/1.1" 304 0
[20/Sep/2016 20:24:23] "GET /arquivos_estaticos/datatable/plugins/select/Select-1.1.2/js/dataTables.select.min.js HTTP/1.1" 304 0
[20/Sep/2016 20:24:23] "GET /arquivos_estaticos/jquery/jquery-ui-1.11.4/jquery-ui.css HTTP/1.1" 304 0
[20/Sep/2016 20:24:23] "GET /arquivos_estaticos/jquery/jquery-editable-select/jquery.editable-select.min.css HTTP/1.1" 304 0
[20/Sep/2016 20:24:23] "GET /arquivos_estaticos/jquery/jquery-editable-select/jquery.editable-select.min.js HTTP/1.1" 304 0
[20/Sep/2016 20:24:23] "GET /arquivos_estaticos/scripts/padrao/controle_botoes.js HTTP/1.1" 304 0
[20/Sep/2016 20:24:23] "GET /arquivos_estaticos/scripts/protocolo/protocolo.js HTTP/1.1" 304 0
[20/Sep/2016 20:24:23] "GET /arquivos_estaticos/angular-1.5.8/angular.min.js HTTP/1.1" 304 0
[20/Sep/2016 20:24:23] "GET /arquivos_estaticos/adminlte/js/app.min.js HTTP/1.1" 304 0
[20/Sep/2016 20:24:23] "GET /arquivos_estaticos/scripts/mask.js HTTP/1.1" 304 0
[20/Sep/2016 20:24:27] "GET /arquivos_estaticos/imagens/logo.png HTTP/1.1" 304 0
[20/Sep/2016 20:24:27] "GET /arquivos_estaticos/imagens/avatar5.png HTTP/1.1" 304 0
olha os contatos desse cliente: [<contato: (27) 32843151>]
[20/Sep/2016 20:25:52] "GET /entidade/visualizar/7/ HTTP/1.1" 200 66690
olha os contatos desse cliente: [<contato: (27) 32843151>]
[20/Sep/2016 20:28:40] "GET /entidade/visualizar/7/ HTTP/1.1" 200 66715
olha os contatos desse cliente: [<contato: (27) 32843151>]
[20/Sep/2016 20:34:31] "GET /entidade/visualizar/7/ HTTP/1.1" 200 66828
[20/Sep/2016 20:34:31] "GET /arquivos_estaticos/jquery/jquery-2.2.0.min.js HTTP/1.1" 304 0
[20/Sep/2016 20:34:31] "GET /arquivos_estaticos/jquery/jquery-ui-1.11.4/jquery-ui.js HTTP/1.1" 304 0
[20/Sep/2016 20:34:31] "GET /arquivos_estaticos/bootstrap/css/bootstrap.min.css HTTP/1.1" 304 0
[20/Sep/2016 20:34:31] "GET /arquivos_estaticos/adminlte/css/AdminLTE.min.css HTTP/1.1" 304 0
[20/Sep/2016 20:34:31] "GET /arquivos_estaticos/icones/css/font-awesome.min.css HTTP/1.1" 304 0
[20/Sep/2016 20:34:31] "GET /arquivos_estaticos/bootstrap/js/bootstrap.min.js HTTP/1.1" 304 0
[20/Sep/2016 20:34:31] "GET /arquivos_estaticos/adminlte/css/skins/skin-blue.min.css HTTP/1.1" 304 0
[20/Sep/2016 20:34:31] "GET /arquivos_estaticos/datatable/DataTables-1.10.11/css/dataTables.bootstrap.min.css HTTP/1.1" 304 0
[20/Sep/2016 20:34:32] "GET /arquivos_estaticos/datatable/plugins/responsivo/Responsive-2.0.2/css/responsive.bootstrap.min.css HTTP/1.1" 304 0
[20/Sep/2016 20:34:32] "GET /arquivos_estaticos/datatable/plugins/select/Select-1.1.2/css/select.bootstrap.min.css HTTP/1.1" 304 0
[20/Sep/2016 20:34:32] "GET /arquivos_estaticos/datatable/DataTables-1.10.11/js/jquery.dataTables.min.js HTTP/1.1" 304 0
[20/Sep/2016 20:34:32] "GET /arquivos_estaticos/datatable/DataTables-1.10.11/js/dataTables.bootstrap.min.js HTTP/1.1" 304 0
[20/Sep/2016 20:34:32] "GET /arquivos_estaticos/datatable/plugins/select/Select-1.1.2/js/dataTables.select.min.js HTTP/1.1" 304 0
[20/Sep/2016 20:34:32] "GET /arquivos_estaticos/jquery/jquery-ui-1.11.4/jquery-ui.css HTTP/1.1" 304 0
[20/Sep/2016 20:34:32] "GET /arquivos_estaticos/jquery/jquery-editable-select/jquery.editable-select.min.css HTTP/1.1" 304 0
[20/Sep/2016 20:34:32] "GET /arquivos_estaticos/jquery/jquery-editable-select/jquery.editable-select.min.js HTTP/1.1" 304 0
[20/Sep/2016 20:34:32] "GET /arquivos_estaticos/scripts/padrao/controle_botoes.js HTTP/1.1" 304 0
[20/Sep/2016 20:34:32] "GET /arquivos_estaticos/scripts/protocolo/protocolo.js HTTP/1.1" 304 0
[20/Sep/2016 20:34:33] "GET /arquivos_estaticos/angular-1.5.8/angular.min.js HTTP/1.1" 304 0
[20/Sep/2016 20:34:33] "GET /arquivos_estaticos/adminlte/js/app.min.js HTTP/1.1" 304 0
[20/Sep/2016 20:34:33] "GET /arquivos_estaticos/scripts/mask.js HTTP/1.1" 304 0
[20/Sep/2016 20:34:33] "GET /arquivos_estaticos/imagens/logo.png HTTP/1.1" 304 0
[20/Sep/2016 20:34:33] "GET /arquivos_estaticos/imagens/avatar5.png HTTP/1.1" 304 0
olha os contatos desse cliente: [<contato: (27) 32843151>]
[20/Sep/2016 20:46:37] "GET /entidade/visualizar/7/ HTTP/1.1" 200 66835
[20/Sep/2016 20:46:37] "GET /arquivos_estaticos/jquery/jquery-2.2.0.min.js HTTP/1.1" 304 0
[20/Sep/2016 20:46:37] "GET /arquivos_estaticos/jquery/jquery-ui-1.11.4/jquery-ui.js HTTP/1.1" 304 0
[20/Sep/2016 20:46:37] "GET /arquivos_estaticos/bootstrap/css/bootstrap.min.css HTTP/1.1" 304 0
[20/Sep/2016 20:46:38] "GET /arquivos_estaticos/bootstrap/js/bootstrap.min.js HTTP/1.1" 304 0
[20/Sep/2016 20:46:38] "GET /arquivos_estaticos/icones/css/font-awesome.min.css HTTP/1.1" 304 0
[20/Sep/2016 20:46:38] "GET /arquivos_estaticos/adminlte/css/AdminLTE.min.css HTTP/1.1" 304 0
[20/Sep/2016 20:46:38] "GET /arquivos_estaticos/adminlte/css/skins/skin-blue.min.css HTTP/1.1" 304 0
[20/Sep/2016 20:46:38] "GET /arquivos_estaticos/datatable/DataTables-1.10.11/css/dataTables.bootstrap.min.css HTTP/1.1" 304 0
[20/Sep/2016 20:46:39] "GET /arquivos_estaticos/datatable/plugins/responsivo/Responsive-2.0.2/css/responsive.bootstrap.min.css HTTP/1.1" 304 0
[20/Sep/2016 20:46:39] "GET /arquivos_estaticos/datatable/plugins/select/Select-1.1.2/css/select.bootstrap.min.css HTTP/1.1" 304 0
[20/Sep/2016 20:46:39] "GET /arquivos_estaticos/datatable/DataTables-1.10.11/js/jquery.dataTables.min.js HTTP/1.1" 304 0
[20/Sep/2016 20:46:39] "GET /arquivos_estaticos/datatable/DataTables-1.10.11/js/dataTables.bootstrap.min.js HTTP/1.1" 304 0
[20/Sep/2016 20:46:40] "GET /arquivos_estaticos/datatable/plugins/select/Select-1.1.2/js/dataTables.select.min.js HTTP/1.1" 304 0
[20/Sep/2016 20:46:40] "GET /arquivos_estaticos/jquery/jquery-ui-1.11.4/jquery-ui.css HTTP/1.1" 304 0
[20/Sep/2016 20:46:40] "GET /arquivos_estaticos/jquery/jquery-editable-select/jquery.editable-select.min.css HTTP/1.1" 304 0
[20/Sep/2016 20:46:40] "GET /arquivos_estaticos/jquery/jquery-editable-select/jquery.editable-select.min.js HTTP/1.1" 304 0
[20/Sep/2016 20:46:40] "GET /arquivos_estaticos/scripts/padrao/controle_botoes.js HTTP/1.1" 304 0
[20/Sep/2016 20:46:40] "GET /arquivos_estaticos/scripts/protocolo/protocolo.js HTTP/1.1" 304 0
[20/Sep/2016 20:46:40] "GET /arquivos_estaticos/scripts/mask.js HTTP/1.1" 304 0
[20/Sep/2016 20:46:41] "GET /arquivos_estaticos/angular-1.5.8/angular.min.js HTTP/1.1" 304 0
[20/Sep/2016 20:46:41] "GET /arquivos_estaticos/adminlte/js/app.min.js HTTP/1.1" 304 0
[20/Sep/2016 20:46:43] "GET /arquivos_estaticos/imagens/logo.png HTTP/1.1" 304 0
[20/Sep/2016 20:46:43] "GET /arquivos_estaticos/imagens/avatar5.png HTTP/1.1" 304 0
olha os contatos desse cliente: [<contato: (27) 32843151>]
[20/Sep/2016 21:09:11] "GET /entidade/visualizar/7/ HTTP/1.1" 200 66835
[20/Sep/2016 21:10:34] "GET / HTTP/1.1" 200 14418
olha os contatos desse cliente: [<contato: (27) 32843151>]
[20/Sep/2016 21:10:38] "GET /entidade/visualizar/7/ HTTP/1.1" 200 66898
olha os contatos desse cliente: [<contato: (27) 32843151>]
[20/Sep/2016 21:12:40] "GET /entidade/visualizar/7/ HTTP/1.1" 200 66877
olha os contatos desse cliente: [<contato: (27) 32843151>]
[20/Sep/2016 21:13:02] "GET /entidade/visualizar/7/ HTTP/1.1" 200 66890
[20/Sep/2016 21:13:02] "GET /arquivos_estaticos/adminlte/css/AdminLTE.min.css HTTP/1.1" 304 0
[20/Sep/2016 21:13:03] "GET /arquivos_estaticos/icones/css/font-awesome.min.css HTTP/1.1" 304 0
[20/Sep/2016 21:13:03] "GET /arquivos_estaticos/bootstrap/js/bootstrap.min.js HTTP/1.1" 304 0
[20/Sep/2016 21:13:03] "GET /arquivos_estaticos/bootstrap/css/bootstrap.min.css HTTP/1.1" 304 0
[20/Sep/2016 21:13:03] "GET /arquivos_estaticos/jquery/jquery-ui-1.11.4/jquery-ui.js HTTP/1.1" 304 0
[20/Sep/2016 21:13:03] "GET /arquivos_estaticos/jquery/jquery-2.2.0.min.js HTTP/1.1" 304 0
[20/Sep/2016 21:13:04] "GET /arquivos_estaticos/adminlte/css/skins/skin-blue.min.css HTTP/1.1" 304 0
[20/Sep/2016 21:13:04] "GET /arquivos_estaticos/datatable/DataTables-1.10.11/css/dataTables.bootstrap.min.css HTTP/1.1" 304 0
[20/Sep/2016 21:13:04] "GET /arquivos_estaticos/datatable/plugins/responsivo/Responsive-2.0.2/css/responsive.bootstrap.min.css HTTP/1.1" 304 0
[20/Sep/2016 21:13:05] "GET /arquivos_estaticos/datatable/plugins/select/Select-1.1.2/css/select.bootstrap.min.css HTTP/1.1" 304 0
[20/Sep/2016 21:13:05] "GET /arquivos_estaticos/datatable/DataTables-1.10.11/js/jquery.dataTables.min.js HTTP/1.1" 304 0
[20/Sep/2016 21:13:05] "GET /arquivos_estaticos/datatable/DataTables-1.10.11/js/dataTables.bootstrap.min.js HTTP/1.1" 304 0
[20/Sep/2016 21:13:05] "GET /arquivos_estaticos/datatable/plugins/select/Select-1.1.2/js/dataTables.select.min.js HTTP/1.1" 304 0
[20/Sep/2016 21:13:05] "GET /arquivos_estaticos/jquery/jquery-ui-1.11.4/jquery-ui.css HTTP/1.1" 304 0
[20/Sep/2016 21:13:05] "GET /arquivos_estaticos/jquery/jquery-editable-select/jquery.editable-select.min.css HTTP/1.1" 304 0
[20/Sep/2016 21:13:05] "GET /arquivos_estaticos/jquery/jquery-editable-select/jquery.editable-select.min.js HTTP/1.1" 304 0
[20/Sep/2016 21:13:05] "GET /arquivos_estaticos/scripts/padrao/controle_botoes.js HTTP/1.1" 304 0
[20/Sep/2016 21:13:05] "GET /arquivos_estaticos/scripts/protocolo/protocolo.js HTTP/1.1" 304 0
[20/Sep/2016 21:13:05] "GET /arquivos_estaticos/angular-1.5.8/angular.min.js HTTP/1.1" 304 0
[20/Sep/2016 21:13:06] "GET /arquivos_estaticos/adminlte/js/app.min.js HTTP/1.1" 304 0
[20/Sep/2016 21:13:06] "GET /arquivos_estaticos/scripts/mask.js HTTP/1.1" 304 0
[20/Sep/2016 21:13:06] "GET /arquivos_estaticos/imagens/avatar5.png HTTP/1.1" 304 0
[20/Sep/2016 21:13:06] "GET /arquivos_estaticos/imagens/logo.png HTTP/1.1" 304 0
olha os contatos desse cliente: [<contato: (27) 32843151>]
[20/Sep/2016 21:13:55] "GET /entidade/visualizar/7/ HTTP/1.1" 200 66896
olha os contatos desse cliente: [<contato: (27) 32843151>]
[20/Sep/2016 21:14:48] "GET /entidade/visualizar/7/ HTTP/1.1" 200 66894
olha os contatos desse cliente: [<contato: (27) 32843151>]
[20/Sep/2016 21:17:19] "GET /entidade/visualizar/7/ HTTP/1.1" 200 67098
olha os contatos desse cliente: [<contato: (27) 32843151>]
[20/Sep/2016 21:29:03] "GET /entidade/visualizar/7/ HTTP/1.1" 200 65249
olha os contatos desse cliente: [<contato: (27) 32843151>]
[20/Sep/2016 21:30:11] "GET /entidade/visualizar/7/ HTTP/1.1" 200 65396
olha os contatos desse cliente: [<contato: (27) 32843151>]
[20/Sep/2016 21:32:24] "GET /entidade/visualizar/7/ HTTP/1.1" 200 65404
olha os contatos desse cliente: [<contato: (27) 32843151>]
[20/Sep/2016 23:28:19] "GET /entidade/visualizar/7/ HTTP/1.1" 200 65412
olha os contatos desse cliente: [<contato: (27) 32843151>]
[20/Sep/2016 23:29:16] "GET /entidade/visualizar/7/ HTTP/1.1" 200 65265
[20/Sep/2016 23:39:26] "GET /entidade/cadastro/ HTTP/1.1" 200 40928
[20/Sep/2016 23:39:27] "GET /arquivos_estaticos/datatable/datatables/media/js/jquery.dataTables.min.js HTTP/1.1" 404 1799
[20/Sep/2016 23:39:27] "GET /arquivos_estaticos/datatable/datatables-plugins/integration/bootstrap/3/dataTables.bootstrap.min.js HTTP/1.1" 404 1877
[20/Sep/2016 23:39:28] "GET /arquivos_estaticos/datatable/datatables-plugins/integration/bootstrap/3/dataTables.bootstrap.min.js HTTP/1.1" 404 1877
olha os contatos desse cliente: [<contato: (22) 222222222>, <contato: (27) 999881254>]
[20/Sep/2016 23:39:30] "GET /entidade/visualizar/2/ HTTP/1.1" 200 65145
Performing system checks...

System check identified no issues (0 silenced).
September 20, 2016 - 23:41:56
Django version 1.9.7, using settings 'sistema_contabil.settings'
Starting development server at http://localhost:8000/
Quit the server with CTRL-BREAK.
Internal Server Error: /entidade/visualizar/2/
Traceback (most recent call last):
  File "C:\Python27\lib\site-packages\django\core\handlers\base.py", line 134, in get_response
    resolver_match = resolver.resolve(request.path_info)
  File "C:\Python27\lib\site-packages\django\core\urlresolvers.py", line 376, in resolve
    sub_match = pattern.resolve(new_path)
  File "C:\Python27\lib\site-packages\django\core\urlresolvers.py", line 248, in resolve
    return ResolverMatch(self.callback, args, kwargs, self.name)
  File "C:\Python27\lib\site-packages\django\core\urlresolvers.py", line 255, in callback
    self._callback = get_callable(self._callback_str)
  File "C:\Python27\lib\site-packages\django\utils\lru_cache.py", line 100, in wrapper
    result = user_function(*args, **kwds)
  File "C:\Python27\lib\site-packages\django\core\urlresolvers.py", line 115, in get_callable
    mod = import_module(mod_name)
  File "C:\Python27\lib\importlib\__init__.py", line 37, in import_module
    __import__(name)
  File "C:\Users\diego\OneDrive\Projetos\sistema_contabil\entidade\views.py", line 557
    'minhas_atividades',minhas_atividades,
                       ^
SyntaxError: invalid syntax
Internal Server Error: /entidade/visualizar/2/
Traceback (most recent call last):
  File "C:\Python27\lib\site-packages\django\core\handlers\base.py", line 134, in get_response
    resolver_match = resolver.resolve(request.path_info)
  File "C:\Python27\lib\site-packages\django\core\urlresolvers.py", line 376, in resolve
    sub_match = pattern.resolve(new_path)
  File "C:\Python27\lib\site-packages\django\core\urlresolvers.py", line 248, in resolve
    return ResolverMatch(self.callback, args, kwargs, self.name)
  File "C:\Python27\lib\site-packages\django\core\urlresolvers.py", line 255, in callback
    self._callback = get_callable(self._callback_str)
  File "C:\Python27\lib\site-packages\django\utils\lru_cache.py", line 100, in wrapper
    result = user_function(*args, **kwds)
  File "C:\Python27\lib\site-packages\django\core\urlresolvers.py", line 115, in get_callable
    mod = import_module(mod_name)
  File "C:\Python27\lib\importlib\__init__.py", line 37, in import_module
    __import__(name)
  File "C:\Users\diego\OneDrive\Projetos\sistema_contabil\entidade\views.py", line 557
    'minhas_atividades',minhas_atividades,
                       ^
SyntaxError: invalid syntax
[20/Sep/2016 23:46:40] "GET /entidade/visualizar/2/ HTTP/1.1" 500 78204
[20/Sep/2016 23:47:09] "GET /entidade/visualizar/2/ HTTP/1.1" 200 65328
[20/Sep/2016 23:47:09] "GET /arquivos_estaticos/jquery/jquery-2.2.0.min.js HTTP/1.1" 304 0
[20/Sep/2016 23:47:09] "GET /arquivos_estaticos/jquery/jquery-ui-1.11.4/jquery-ui.js HTTP/1.1" 304 0
[20/Sep/2016 23:47:09] "GET /arquivos_estaticos/icones/css/font-awesome.min.css HTTP/1.1" 304 0
[20/Sep/2016 23:47:09] "GET /arquivos_estaticos/bootstrap/css/bootstrap.min.css HTTP/1.1" 304 0
[20/Sep/2016 23:47:09] "GET /arquivos_estaticos/bootstrap/js/bootstrap.min.js HTTP/1.1" 304 0
[20/Sep/2016 23:47:09] "GET /arquivos_estaticos/adminlte/css/AdminLTE.min.css HTTP/1.1" 304 0
[20/Sep/2016 23:47:09] "GET /arquivos_estaticos/adminlte/css/skins/skin-blue.min.css HTTP/1.1" 304 0
[20/Sep/2016 23:47:09] "GET /arquivos_estaticos/datatable/DataTables-1.10.11/css/dataTables.bootstrap.min.css HTTP/1.1" 304 0
[20/Sep/2016 23:47:09] "GET /arquivos_estaticos/datatable/plugins/responsivo/Responsive-2.0.2/css/responsive.bootstrap.min.css HTTP/1.1" 304 0
[20/Sep/2016 23:47:09] "GET /arquivos_estaticos/datatable/plugins/select/Select-1.1.2/css/select.bootstrap.min.css HTTP/1.1" 304 0
[20/Sep/2016 23:47:09] "GET /arquivos_estaticos/datatable/DataTables-1.10.11/js/jquery.dataTables.min.js HTTP/1.1" 304 0
[20/Sep/2016 23:47:09] "GET /arquivos_estaticos/datatable/DataTables-1.10.11/js/dataTables.bootstrap.min.js HTTP/1.1" 304 0
[20/Sep/2016 23:47:09] "GET /arquivos_estaticos/datatable/plugins/select/Select-1.1.2/js/dataTables.select.min.js HTTP/1.1" 304 0
[20/Sep/2016 23:47:09] "GET /arquivos_estaticos/jquery/jquery-ui-1.11.4/jquery-ui.css HTTP/1.1" 304 0
[20/Sep/2016 23:47:09] "GET /arquivos_estaticos/jquery/jquery-editable-select/jquery.editable-select.min.css HTTP/1.1" 304 0
[20/Sep/2016 23:47:10] "GET /arquivos_estaticos/jquery/jquery-editable-select/jquery.editable-select.min.js HTTP/1.1" 304 0
[20/Sep/2016 23:47:10] "GET /arquivos_estaticos/scripts/padrao/controle_botoes.js HTTP/1.1" 304 0
[20/Sep/2016 23:47:10] "GET /arquivos_estaticos/scripts/protocolo/protocolo.js HTTP/1.1" 304 0
[20/Sep/2016 23:47:10] "GET /arquivos_estaticos/angular-1.5.8/angular.min.js HTTP/1.1" 304 0
[20/Sep/2016 23:47:10] "GET /arquivos_estaticos/adminlte/js/app.min.js HTTP/1.1" 304 0
[20/Sep/2016 23:47:10] "GET /arquivos_estaticos/scripts/mask.js HTTP/1.1" 304 0
[20/Sep/2016 23:47:11] "GET /arquivos_estaticos/imagens/logo.png HTTP/1.1" 304 0
[20/Sep/2016 23:47:11] "GET /arquivos_estaticos/imagens/avatar5.png HTTP/1.1" 304 0
Performing system checks...

System check identified no issues (0 silenced).
September 20, 2016 - 23:47:47
Django version 1.9.7, using settings 'sistema_contabil.settings'
Starting development server at http://localhost:8000/
Quit the server with CTRL-BREAK.
olha minhas atividades: [<AtividadeEconomica: AtividadeEconomica object>]
[20/Sep/2016 23:47:48] "GET /entidade/visualizar/2/ HTTP/1.1" 200 65328
[20/Sep/2016 23:47:48] "GET /arquivos_estaticos/jquery/jquery-2.2.0.min.js HTTP/1.1" 304 0
[20/Sep/2016 23:47:48] "GET /arquivos_estaticos/jquery/jquery-ui-1.11.4/jquery-ui.js HTTP/1.1" 304 0
[20/Sep/2016 23:47:48] "GET /arquivos_estaticos/adminlte/css/skins/skin-blue.min.css HTTP/1.1" 304 0
[20/Sep/2016 23:47:48] "GET /arquivos_estaticos/adminlte/css/AdminLTE.min.css HTTP/1.1" 304 0
[20/Sep/2016 23:47:48] "GET /arquivos_estaticos/icones/css/font-awesome.min.css HTTP/1.1" 304 0
[20/Sep/2016 23:47:48] "GET /arquivos_estaticos/bootstrap/js/bootstrap.min.js HTTP/1.1" 304 0
[20/Sep/2016 23:47:48] "GET /arquivos_estaticos/bootstrap/css/bootstrap.min.css HTTP/1.1" 304 0
[20/Sep/2016 23:47:48] "GET /arquivos_estaticos/datatable/DataTables-1.10.11/css/dataTables.bootstrap.min.css HTTP/1.1" 304 0
[20/Sep/2016 23:47:48] "GET /arquivos_estaticos/datatable/plugins/responsivo/Responsive-2.0.2/css/responsive.bootstrap.min.css HTTP/1.1" 304 0
[20/Sep/2016 23:47:48] "GET /arquivos_estaticos/datatable/plugins/select/Select-1.1.2/css/select.bootstrap.min.css HTTP/1.1" 304 0
[20/Sep/2016 23:47:48] "GET /arquivos_estaticos/datatable/DataTables-1.10.11/js/jquery.dataTables.min.js HTTP/1.1" 304 0
[20/Sep/2016 23:47:48] "GET /arquivos_estaticos/datatable/DataTables-1.10.11/js/dataTables.bootstrap.min.js HTTP/1.1" 304 0
[20/Sep/2016 23:47:48] "GET /arquivos_estaticos/datatable/plugins/select/Select-1.1.2/js/dataTables.select.min.js HTTP/1.1" 304 0
[20/Sep/2016 23:47:48] "GET /arquivos_estaticos/jquery/jquery-ui-1.11.4/jquery-ui.css HTTP/1.1" 304 0
[20/Sep/2016 23:47:48] "GET /arquivos_estaticos/jquery/jquery-editable-select/jquery.editable-select.min.css HTTP/1.1" 304 0
[20/Sep/2016 23:47:48] "GET /arquivos_estaticos/jquery/jquery-editable-select/jquery.editable-select.min.js HTTP/1.1" 304 0
[20/Sep/2016 23:47:48] "GET /arquivos_estaticos/scripts/padrao/controle_botoes.js HTTP/1.1" 304 0
[20/Sep/2016 23:47:48] "GET /arquivos_estaticos/scripts/protocolo/protocolo.js HTTP/1.1" 304 0
[20/Sep/2016 23:47:48] "GET /arquivos_estaticos/angular-1.5.8/angular.min.js HTTP/1.1" 304 0
[20/Sep/2016 23:47:48] "GET /arquivos_estaticos/adminlte/js/app.min.js HTTP/1.1" 304 0
[20/Sep/2016 23:47:48] "GET /arquivos_estaticos/scripts/mask.js HTTP/1.1" 304 0
[20/Sep/2016 23:47:49] "GET /arquivos_estaticos/imagens/logo.png HTTP/1.1" 304 0
[20/Sep/2016 23:47:49] "GET /arquivos_estaticos/imagens/avatar5.png HTTP/1.1" 304 0
olha minhas atividades: [<AtividadeEconomica: AtividadeEconomica object>]
[20/Sep/2016 23:49:51] "GET /entidade/visualizar/2/ HTTP/1.1" 200 65324
olha minhas atividades: [<AtividadeEconomica: AtividadeEconomica object>]
[20/Sep/2016 23:51:40] "GET /entidade/visualizar/2/ HTTP/1.1" 200 65320
Internal Server Error: /entidade/visualizar/2/
Traceback (most recent call last):
  File "C:\Python27\lib\site-packages\django\core\handlers\base.py", line 158, in get_response
    % (callback.__module__, view_name))
ValueError: The view entidade.views.visualizar_entidade didn't return an HttpResponse object. It returned None instead.
Internal Server Error: /entidade/visualizar/2/
Traceback (most recent call last):
  File "C:\Python27\lib\site-packages\django\core\handlers\base.py", line 158, in get_response
    % (callback.__module__, view_name))
ValueError: The view entidade.views.visualizar_entidade didn't return an HttpResponse object. It returned None instead.
[20/Sep/2016 23:52:31] "POST /entidade/visualizar/2/ HTTP/1.1" 500 57923
Performing system checks...

System check identified no issues (0 silenced).
September 20, 2016 - 23:54:51
Django version 1.9.7, using settings 'sistema_contabil.settings'
Starting development server at http://localhost:8000/
Quit the server with CTRL-BREAK.
Internal Server Error: /entidade/visualizar/2/
Traceback (most recent call last):
  File "C:\Python27\lib\site-packages\django\core\handlers\base.py", line 149, in get_response
    response = self.process_exception_by_middleware(e, request)
  File "C:\Python27\lib\site-packages\django\core\handlers\base.py", line 147, in get_response
    response = wrapped_callback(request, *callback_args, **callback_kwargs)
  File "C:\Users\diego\OneDrive\Projetos\sistema_contabil\entidade\views.py", line 519, in visualizar_entidade
    return adicionar_entidade(request)
  File "C:\Users\diego\OneDrive\Projetos\sistema_contabil\entidade\views.py", line 573, in adicionar_entidade
    registro_entidade    = formulario.get_entidade(formulario)
  File "C:\Users\diego\OneDrive\Projetos\sistema_contabil\entidade\formularios.py", line 195, in get_object_entidade
    registro.observacoes = formulario.cleaned_data['observacoes      ']
KeyError: 'observacoes      '
Internal Server Error: /entidade/visualizar/2/
Traceback (most recent call last):
  File "C:\Python27\lib\site-packages\django\core\handlers\base.py", line 149, in get_response
    response = self.process_exception_by_middleware(e, request)
  File "C:\Python27\lib\site-packages\django\core\handlers\base.py", line 147, in get_response
    response = wrapped_callback(request, *callback_args, **callback_kwargs)
  File "C:\Users\diego\OneDrive\Projetos\sistema_contabil\entidade\views.py", line 519, in visualizar_entidade
    return adicionar_entidade(request)
  File "C:\Users\diego\OneDrive\Projetos\sistema_contabil\entidade\views.py", line 573, in adicionar_entidade
    registro_entidade    = formulario.get_entidade(formulario)
  File "C:\Users\diego\OneDrive\Projetos\sistema_contabil\entidade\formularios.py", line 195, in get_object_entidade
    registro.observacoes = formulario.cleaned_data['observacoes      ']
KeyError: 'observacoes      '
[20/Sep/2016 23:54:52] "POST /entidade/visualizar/2/ HTTP/1.1" 500 77321
Performing system checks...

System check identified no issues (0 silenced).
September 20, 2016 - 23:56:57
Django version 1.9.7, using settings 'sistema_contabil.settings'
Starting development server at http://localhost:8000/
Quit the server with CTRL-BREAK.
Erro! Excecao: Erro! Exceção:UNIQUE constraint failed: entidade_entidade.cpf_cnpj
[21/Sep/2016 00:02:14] "POST /entidade/visualizar/2/ HTTP/1.1" 200 352355
[21/Sep/2016 00:02:14] "GET /arquivos_estaticos/jquery/jquery-2.2.0.min.js HTTP/1.1" 304 0
[21/Sep/2016 00:02:14] "GET /arquivos_estaticos/bootstrap/css/bootstrap.min.css HTTP/1.1" 304 0
[21/Sep/2016 00:02:14] "GET /arquivos_estaticos/jquery/jquery-ui-1.11.4/jquery-ui.js HTTP/1.1" 304 0
[21/Sep/2016 00:02:14] "GET /arquivos_estaticos/icones/css/font-awesome.min.css HTTP/1.1" 304 0
[21/Sep/2016 00:02:14] "GET /arquivos_estaticos/bootstrap/js/bootstrap.min.js HTTP/1.1" 304 0
[21/Sep/2016 00:02:14] "GET /arquivos_estaticos/adminlte/css/AdminLTE.min.css HTTP/1.1" 304 0
[21/Sep/2016 00:02:14] "GET /arquivos_estaticos/datatable/DataTables-1.10.11/css/dataTables.bootstrap.min.css HTTP/1.1" 304 0
[21/Sep/2016 00:02:15] "GET /arquivos_estaticos/adminlte/css/skins/skin-blue.min.css HTTP/1.1" 304 0
[21/Sep/2016 00:02:15] "GET /arquivos_estaticos/datatable/plugins/responsivo/Responsive-2.0.2/css/responsive.bootstrap.min.css HTTP/1.1" 304 0
[21/Sep/2016 00:02:15] "GET /arquivos_estaticos/datatable/plugins/select/Select-1.1.2/css/select.bootstrap.min.css HTTP/1.1" 304 0
[21/Sep/2016 00:02:15] "GET /arquivos_estaticos/datatable/DataTables-1.10.11/js/jquery.dataTables.min.js HTTP/1.1" 304 0
[21/Sep/2016 00:02:15] "GET /arquivos_estaticos/datatable/DataTables-1.10.11/js/dataTables.bootstrap.min.js HTTP/1.1" 304 0
[21/Sep/2016 00:02:15] "GET /arquivos_estaticos/datatable/plugins/select/Select-1.1.2/js/dataTables.select.min.js HTTP/1.1" 304 0
[21/Sep/2016 00:02:15] "GET /arquivos_estaticos/jquery/jquery-ui-1.11.4/jquery-ui.css HTTP/1.1" 304 0
[21/Sep/2016 00:02:15] "GET /arquivos_estaticos/jquery/jquery-editable-select/jquery.editable-select.min.css HTTP/1.1" 304 0
[21/Sep/2016 00:02:15] "GET /arquivos_estaticos/jquery/jquery-editable-select/jquery.editable-select.min.js HTTP/1.1" 304 0
[21/Sep/2016 00:02:15] "GET /arquivos_estaticos/scripts/padrao/controle_botoes.js HTTP/1.1" 304 0
[21/Sep/2016 00:02:15] "GET /arquivos_estaticos/scripts/protocolo/protocolo.js HTTP/1.1" 304 0
[21/Sep/2016 00:02:15] "GET /arquivos_estaticos/angular-1.5.8/angular.min.js HTTP/1.1" 304 0
[21/Sep/2016 00:02:15] "GET /arquivos_estaticos/adminlte/js/app.min.js HTTP/1.1" 304 0
[21/Sep/2016 00:02:15] "GET /arquivos_estaticos/scripts/mask.js HTTP/1.1" 304 0
[21/Sep/2016 00:02:17] "GET /arquivos_estaticos/imagens/logo.png HTTP/1.1" 304 0
[21/Sep/2016 00:02:17] "GET /arquivos_estaticos/imagens/avatar5.png HTTP/1.1" 304 0
serializar:  (22) 222222222
serializar:  (27) 999881254
[21/Sep/2016 00:02:46] "GET /entidade/visualizar/2/ HTTP/1.1" 200 65320
Performing system checks...

System check identified no issues (0 silenced).
September 21, 2016 - 00:06:17
Django version 1.9.7, using settings 'sistema_contabil.settings'
Starting development server at http://localhost:8000/
Quit the server with CTRL-BREAK.
[21/Sep/2016 00:07:46] "GET /entidade/visualizar/2/ HTTP/1.1" 200 65443
[21/Sep/2016 00:08:03] "GET /entidade/visualizar/2/ HTTP/1.1" 200 65443
[21/Sep/2016 00:08:03] "GET /arquivos_estaticos/jquery/jquery-2.2.0.min.js HTTP/1.1" 304 0
[21/Sep/2016 00:08:03] "GET /arquivos_estaticos/jquery/jquery-ui-1.11.4/jquery-ui.js HTTP/1.1" 304 0
[21/Sep/2016 00:08:03] "GET /arquivos_estaticos/icones/css/font-awesome.min.css HTTP/1.1" 304 0
[21/Sep/2016 00:08:03] "GET /arquivos_estaticos/bootstrap/css/bootstrap.min.css HTTP/1.1" 304 0
[21/Sep/2016 00:08:03] "GET /arquivos_estaticos/bootstrap/js/bootstrap.min.js HTTP/1.1" 304 0
[21/Sep/2016 00:08:03] "GET /arquivos_estaticos/adminlte/css/AdminLTE.min.css HTTP/1.1" 304 0
[21/Sep/2016 00:08:03] "GET /arquivos_estaticos/adminlte/css/skins/skin-blue.min.css HTTP/1.1" 304 0
[21/Sep/2016 00:08:03] "GET /arquivos_estaticos/datatable/plugins/responsivo/Responsive-2.0.2/css/responsive.bootstrap.min.css HTTP/1.1" 304 0
[21/Sep/2016 00:08:03] "GET /arquivos_estaticos/datatable/DataTables-1.10.11/css/dataTables.bootstrap.min.css HTTP/1.1" 304 0
[21/Sep/2016 00:08:03] "GET /arquivos_estaticos/datatable/DataTables-1.10.11/js/dataTables.bootstrap.min.js HTTP/1.1" 304 0
[21/Sep/2016 00:08:03] "GET /arquivos_estaticos/datatable/DataTables-1.10.11/js/jquery.dataTables.min.js HTTP/1.1" 304 0
[21/Sep/2016 00:08:03] "GET /arquivos_estaticos/datatable/plugins/select/Select-1.1.2/css/select.bootstrap.min.css HTTP/1.1" 304 0
[21/Sep/2016 00:08:03] "GET /arquivos_estaticos/datatable/plugins/select/Select-1.1.2/js/dataTables.select.min.js HTTP/1.1" 304 0
[21/Sep/2016 00:08:03] "GET /arquivos_estaticos/jquery/jquery-editable-select/jquery.editable-select.min.css HTTP/1.1" 304 0
[21/Sep/2016 00:08:03] "GET /arquivos_estaticos/jquery/jquery-ui-1.11.4/jquery-ui.css HTTP/1.1" 304 0
[21/Sep/2016 00:08:03] "GET /arquivos_estaticos/jquery/jquery-editable-select/jquery.editable-select.min.js HTTP/1.1" 304 0
[21/Sep/2016 00:08:03] "GET /arquivos_estaticos/scripts/padrao/controle_botoes.js HTTP/1.1" 304 0
[21/Sep/2016 00:08:03] "GET /arquivos_estaticos/scripts/protocolo/protocolo.js HTTP/1.1" 304 0
[21/Sep/2016 00:08:03] "GET /arquivos_estaticos/angular-1.5.8/angular.min.js HTTP/1.1" 304 0
[21/Sep/2016 00:08:03] "GET /arquivos_estaticos/adminlte/js/app.min.js HTTP/1.1" 304 0
[21/Sep/2016 00:08:03] "GET /arquivos_estaticos/scripts/mask.js HTTP/1.1" 304 0
[21/Sep/2016 00:08:05] "GET /arquivos_estaticos/imagens/logo.png HTTP/1.1" 304 0
[21/Sep/2016 00:08:05] "GET /arquivos_estaticos/imagens/avatar5.png HTTP/1.1" 304 0
Performing system checks...

System check identified no issues (0 silenced).
September 21, 2016 - 00:08:52
Django version 1.9.7, using settings 'sistema_contabil.settings'
Starting development server at http://localhost:8000/
Quit the server with CTRL-BREAK.
[21/Sep/2016 00:08:52] "GET /entidade/visualizar/2/ HTTP/1.1" 200 65441
Performing system checks...

System check identified no issues (0 silenced).
September 21, 2016 - 00:09:58
Django version 1.9.7, using settings 'sistema_contabil.settings'
Starting development server at http://localhost:8000/
Quit the server with CTRL-BREAK.
[21/Sep/2016 00:09:59] "GET /entidade/visualizar/2/ HTTP/1.1" 200 65423
Erro! Excecao: Erro! Exceção:UNIQUE constraint failed: entidade_entidade.cpf_cnpj
[21/Sep/2016 00:10:24] "POST /entidade/visualizar/2/ HTTP/1.1" 200 352449
Performing system checks...

System check identified no issues (0 silenced).
September 21, 2016 - 00:21:45
Django version 1.9.7, using settings 'sistema_contabil.settings'
Starting development server at http://localhost:8000/
Quit the server with CTRL-BREAK.
Performing system checks...

System check identified no issues (0 silenced).
September 21, 2016 - 00:32:26
Django version 1.9.7, using settings 'sistema_contabil.settings'
Starting development server at http://localhost:8000/
Quit the server with CTRL-BREAK.
Internal Server Error: /entidade/cadastro/
Traceback (most recent call last):
  File "C:\Python27\lib\site-packages\django\core\handlers\base.py", line 134, in get_response
    resolver_match = resolver.resolve(request.path_info)
  File "C:\Python27\lib\site-packages\django\core\urlresolvers.py", line 376, in resolve
    sub_match = pattern.resolve(new_path)
  File "C:\Python27\lib\site-packages\django\core\urlresolvers.py", line 248, in resolve
    return ResolverMatch(self.callback, args, kwargs, self.name)
  File "C:\Python27\lib\site-packages\django\core\urlresolvers.py", line 255, in callback
    self._callback = get_callable(self._callback_str)
  File "C:\Python27\lib\site-packages\django\utils\lru_cache.py", line 100, in wrapper
    result = user_function(*args, **kwds)
  File "C:\Python27\lib\site-packages\django\core\urlresolvers.py", line 115, in get_callable
    mod = import_module(mod_name)
  File "C:\Python27\lib\importlib\__init__.py", line 37, in import_module
    __import__(name)
  File "C:\Users\diego\OneDrive\Projetos\sistema_contabil\entidade\views.py", line 509
    else:
       ^
IndentationError: expected an indented block
Internal Server Error: /entidade/cadastro/
Traceback (most recent call last):
  File "C:\Python27\lib\site-packages\django\core\handlers\base.py", line 134, in get_response
    resolver_match = resolver.resolve(request.path_info)
  File "C:\Python27\lib\site-packages\django\core\urlresolvers.py", line 376, in resolve
    sub_match = pattern.resolve(new_path)
  File "C:\Python27\lib\site-packages\django\core\urlresolvers.py", line 248, in resolve
    return ResolverMatch(self.callback, args, kwargs, self.name)
  File "C:\Python27\lib\site-packages\django\core\urlresolvers.py", line 255, in callback
    self._callback = get_callable(self._callback_str)
  File "C:\Python27\lib\site-packages\django\utils\lru_cache.py", line 100, in wrapper
    result = user_function(*args, **kwds)
  File "C:\Python27\lib\site-packages\django\core\urlresolvers.py", line 115, in get_callable
    mod = import_module(mod_name)
  File "C:\Python27\lib\importlib\__init__.py", line 37, in import_module
    __import__(name)
  File "C:\Users\diego\OneDrive\Projetos\sistema_contabil\entidade\views.py", line 509
    else:
       ^
IndentationError: expected an indented block
[21/Sep/2016 00:46:51] "GET /entidade/cadastro/ HTTP/1.1" 500 77887
Internal Server Error: /entidade/cadastro/
Traceback (most recent call last):
  File "C:\Python27\lib\site-packages\django\core\handlers\base.py", line 134, in get_response
    resolver_match = resolver.resolve(request.path_info)
  File "C:\Python27\lib\site-packages\django\core\urlresolvers.py", line 376, in resolve
    sub_match = pattern.resolve(new_path)
  File "C:\Python27\lib\site-packages\django\core\urlresolvers.py", line 248, in resolve
    return ResolverMatch(self.callback, args, kwargs, self.name)
  File "C:\Python27\lib\site-packages\django\core\urlresolvers.py", line 255, in callback
    self._callback = get_callable(self._callback_str)
  File "C:\Python27\lib\site-packages\django\utils\lru_cache.py", line 100, in wrapper
    result = user_function(*args, **kwds)
  File "C:\Python27\lib\site-packages\django\core\urlresolvers.py", line 115, in get_callable
    mod = import_module(mod_name)
  File "C:\Python27\lib\importlib\__init__.py", line 37, in import_module
    __import__(name)
  File "C:\Users\diego\OneDrive\Projetos\sistema_contabil\entidade\views.py", line 509
    else:
       ^
IndentationError: expected an indented block
Internal Server Error: /entidade/cadastro/
Traceback (most recent call last):
  File "C:\Python27\lib\site-packages\django\core\handlers\base.py", line 134, in get_response
    resolver_match = resolver.resolve(request.path_info)
  File "C:\Python27\lib\site-packages\django\core\urlresolvers.py", line 376, in resolve
    sub_match = pattern.resolve(new_path)
  File "C:\Python27\lib\site-packages\django\core\urlresolvers.py", line 248, in resolve
    return ResolverMatch(self.callback, args, kwargs, self.name)
  File "C:\Python27\lib\site-packages\django\core\urlresolvers.py", line 255, in callback
    self._callback = get_callable(self._callback_str)
  File "C:\Python27\lib\site-packages\django\utils\lru_cache.py", line 100, in wrapper
    result = user_function(*args, **kwds)
  File "C:\Python27\lib\site-packages\django\core\urlresolvers.py", line 115, in get_callable
    mod = import_module(mod_name)
  File "C:\Python27\lib\importlib\__init__.py", line 37, in import_module
    __import__(name)
  File "C:\Users\diego\OneDrive\Projetos\sistema_contabil\entidade\views.py", line 509
    else:
       ^
IndentationError: expected an indented block
[21/Sep/2016 00:46:55] "GET /entidade/cadastro/ HTTP/1.1" 500 77723
Internal Server Error: /entidade/cadastro/
Traceback (most recent call last):
  File "C:\Python27\lib\site-packages\django\core\handlers\base.py", line 134, in get_response
    resolver_match = resolver.resolve(request.path_info)
  File "C:\Python27\lib\site-packages\django\core\urlresolvers.py", line 376, in resolve
    sub_match = pattern.resolve(new_path)
  File "C:\Python27\lib\site-packages\django\core\urlresolvers.py", line 248, in resolve
    return ResolverMatch(self.callback, args, kwargs, self.name)
  File "C:\Python27\lib\site-packages\django\core\urlresolvers.py", line 255, in callback
    self._callback = get_callable(self._callback_str)
  File "C:\Python27\lib\site-packages\django\utils\lru_cache.py", line 100, in wrapper
    result = user_function(*args, **kwds)
  File "C:\Python27\lib\site-packages\django\core\urlresolvers.py", line 115, in get_callable
    mod = import_module(mod_name)
  File "C:\Python27\lib\importlib\__init__.py", line 37, in import_module
    __import__(name)
  File "C:\Users\diego\OneDrive\Projetos\sistema_contabil\entidade\views.py", line 509
    else:
       ^
IndentationError: expected an indented block
Internal Server Error: /entidade/cadastro/
Traceback (most recent call last):
  File "C:\Python27\lib\site-packages\django\core\handlers\base.py", line 134, in get_response
    resolver_match = resolver.resolve(request.path_info)
  File "C:\Python27\lib\site-packages\django\core\urlresolvers.py", line 376, in resolve
    sub_match = pattern.resolve(new_path)
  File "C:\Python27\lib\site-packages\django\core\urlresolvers.py", line 248, in resolve
    return ResolverMatch(self.callback, args, kwargs, self.name)
  File "C:\Python27\lib\site-packages\django\core\urlresolvers.py", line 255, in callback
    self._callback = get_callable(self._callback_str)
  File "C:\Python27\lib\site-packages\django\utils\lru_cache.py", line 100, in wrapper
    result = user_function(*args, **kwds)
  File "C:\Python27\lib\site-packages\django\core\urlresolvers.py", line 115, in get_callable
    mod = import_module(mod_name)
  File "C:\Python27\lib\importlib\__init__.py", line 37, in import_module
    __import__(name)
  File "C:\Users\diego\OneDrive\Projetos\sistema_contabil\entidade\views.py", line 509
    else:
       ^
IndentationError: expected an indented block
[21/Sep/2016 00:47:13] "GET /entidade/cadastro/ HTTP/1.1" 500 77858
[21/Sep/2016 00:47:32] "GET /entidade/cadastro/ HTTP/1.1" 200 40928
[21/Sep/2016 00:47:32] "GET /arquivos_estaticos/jquery/jquery-2.2.0.min.js HTTP/1.1" 304 0
[21/Sep/2016 00:47:32] "GET /arquivos_estaticos/jquery/jquery-ui-1.11.4/jquery-ui.js HTTP/1.1" 304 0
[21/Sep/2016 00:47:32] "GET /arquivos_estaticos/bootstrap/css/bootstrap.min.css HTTP/1.1" 304 0
[21/Sep/2016 00:47:33] "GET /arquivos_estaticos/bootstrap/js/bootstrap.min.js HTTP/1.1" 304 0
[21/Sep/2016 00:47:33] "GET /arquivos_estaticos/adminlte/css/AdminLTE.min.css HTTP/1.1" 304 0
[21/Sep/2016 00:47:33] "GET /arquivos_estaticos/icones/css/font-awesome.min.css HTTP/1.1" 304 0
[21/Sep/2016 00:47:33] "GET /arquivos_estaticos/adminlte/css/skins/skin-blue.min.css HTTP/1.1" 304 0
[21/Sep/2016 00:47:33] "GET /arquivos_estaticos/jquery/jquery-ui-1.11.4/jquery-ui.css HTTP/1.1" 304 0
[21/Sep/2016 00:47:33] "GET /arquivos_estaticos/datatable/DataTables-1.10.11/css/dataTables.bootstrap.min.css HTTP/1.1" 304 0
[21/Sep/2016 00:47:33] "GET /arquivos_estaticos/datatable/plugins/responsivo/Responsive-2.0.2/css/responsive.bootstrap.min.css HTTP/1.1" 304 0
[21/Sep/2016 00:47:33] "GET /arquivos_estaticos/datatable/plugins/select/Select-1.1.2/css/select.bootstrap.min.css HTTP/1.1" 304 0
[21/Sep/2016 00:47:33] "GET /arquivos_estaticos/datatable/DataTables-1.10.11/js/jquery.dataTables.min.js HTTP/1.1" 304 0
[21/Sep/2016 00:47:33] "GET /arquivos_estaticos/datatable/DataTables-1.10.11/js/dataTables.bootstrap.min.js HTTP/1.1" 304 0
[21/Sep/2016 00:47:33] "GET /arquivos_estaticos/datatable/plugins/select/Select-1.1.2/js/dataTables.select.min.js HTTP/1.1" 304 0
[21/Sep/2016 00:47:33] "GET /arquivos_estaticos/adminlte/js/app.min.js HTTP/1.1" 304 0
[21/Sep/2016 00:47:33] "GET /arquivos_estaticos/scripts/mask.js HTTP/1.1" 304 0
[21/Sep/2016 00:47:33] "GET /arquivos_estaticos/datatable/datatables-plugins/integration/bootstrap/3/dataTables.bootstrap.min.js HTTP/1.1" 404 1877
[21/Sep/2016 00:47:33] "GET /arquivos_estaticos/datatable/datatables/media/js/jquery.dataTables.min.js HTTP/1.1" 404 1799
[21/Sep/2016 00:47:35] "GET /arquivos_estaticos/imagens/logo.png HTTP/1.1" 304 0
[21/Sep/2016 00:47:35] "GET /arquivos_estaticos/imagens/avatar5.png HTTP/1.1" 304 0
[21/Sep/2016 00:47:35] "GET /arquivos_estaticos/bootstrap/fonts/glyphicons-halflings-regular.woff2 HTTP/1.1" 304 0
[21/Sep/2016 00:47:35] "GET /arquivos_estaticos/datatable/datatables/media/js/jquery.dataTables.min.js HTTP/1.1" 404 1799
[21/Sep/2016 00:47:35] "GET /arquivos_estaticos/datatable/datatables-plugins/integration/bootstrap/3/dataTables.bootstrap.min.js HTTP/1.1" 404 1877
Performing system checks...

System check identified no issues (0 silenced).
September 21, 2016 - 00:47:56
Django version 1.9.7, using settings 'sistema_contabil.settings'
Starting development server at http://localhost:8000/
Quit the server with CTRL-BREAK.
[21/Sep/2016 01:03:33] "GET /entidade/visualizar/5 HTTP/1.1" 301 0
[21/Sep/2016 01:03:33] "GET /entidade/visualizar/5/ HTTP/1.1" 200 65102
Performing system checks...

System check identified no issues (0 silenced).
September 21, 2016 - 01:16:24
Django version 1.9.7, using settings 'sistema_contabil.settings'
Starting development server at http://localhost:8000/
Quit the server with CTRL-BREAK.
Falha na validacao dos objetos: ['', "'list' object has no attribute 'full_clean'", "'list' object has no attribute 'full_clean'"]
Internal Server Error: /entidade/visualizar/5/
Traceback (most recent call last):
  File "C:\Python27\lib\site-packages\django\core\handlers\base.py", line 149, in get_response
    response = self.process_exception_by_middleware(e, request)
  File "C:\Python27\lib\site-packages\django\core\handlers\base.py", line 147, in get_response
    response = wrapped_callback(request, *callback_args, **callback_kwargs)
  File "C:\Users\diego\OneDrive\Projetos\sistema_contabil\entidade\views.py", line 517, in visualizar_entidade
    messages.add_message(request, messages.SUCCESS, msg)
UnboundLocalError: local variable 'msg' referenced before assignment
Internal Server Error: /entidade/visualizar/5/
Traceback (most recent call last):
  File "C:\Python27\lib\site-packages\django\core\handlers\base.py", line 149, in get_response
    response = self.process_exception_by_middleware(e, request)
  File "C:\Python27\lib\site-packages\django\core\handlers\base.py", line 147, in get_response
    response = wrapped_callback(request, *callback_args, **callback_kwargs)
  File "C:\Users\diego\OneDrive\Projetos\sistema_contabil\entidade\views.py", line 517, in visualizar_entidade
    messages.add_message(request, messages.SUCCESS, msg)
UnboundLocalError: local variable 'msg' referenced before assignment
[21/Sep/2016 01:16:32] "POST /entidade/visualizar/5/ HTTP/1.1" 500 68835
Performing system checks...

System check identified no issues (0 silenced).
September 21, 2016 - 01:17:41
Django version 1.9.7, using settings 'sistema_contabil.settings'
Starting development server at http://localhost:8000/
Quit the server with CTRL-BREAK.
Falha na validacao dos objetos: ['', "'list' object has no attribute 'full_clean'", "'list' object has no attribute 'full_clean'"]
Internal Server Error: /entidade/visualizar/5/
Traceback (most recent call last):
  File "C:\Python27\lib\site-packages\django\core\handlers\base.py", line 158, in get_response
    % (callback.__module__, view_name))
ValueError: The view entidade.views.visualizar_entidade didn't return an HttpResponse object. It returned None instead.
Internal Server Error: /entidade/visualizar/5/
Traceback (most recent call last):
  File "C:\Python27\lib\site-packages\django\core\handlers\base.py", line 158, in get_response
    % (callback.__module__, view_name))
ValueError: The view entidade.views.visualizar_entidade didn't return an HttpResponse object. It returned None instead.
[21/Sep/2016 01:17:46] "POST /entidade/visualizar/5/ HTTP/1.1" 500 58089
Performing system checks...

System check identified no issues (0 silenced).
September 21, 2016 - 01:18:45
Django version 1.9.7, using settings 'sistema_contabil.settings'
Starting development server at http://localhost:8000/
Quit the server with CTRL-BREAK.
HELDER PASTI
[<contato: (27) 999881254>]
[]
Falha na validacao dos objetos: ['', "'list' object has no attribute 'full_clean'", "'list' object has no attribute 'full_clean'"]
Internal Server Error: /entidade/visualizar/5/
Traceback (most recent call last):
  File "C:\Python27\lib\site-packages\django\core\handlers\base.py", line 158, in get_response
    % (callback.__module__, view_name))
ValueError: The view entidade.views.visualizar_entidade didn't return an HttpResponse object. It returned None instead.
Internal Server Error: /entidade/visualizar/5/
Traceback (most recent call last):
  File "C:\Python27\lib\site-packages\django\core\handlers\base.py", line 158, in get_response
    % (callback.__module__, view_name))
ValueError: The view entidade.views.visualizar_entidade didn't return an HttpResponse object. It returned None instead.
[21/Sep/2016 01:18:47] "POST /entidade/visualizar/5/ HTTP/1.1" 500 58089
Performing system checks...

System check identified no issues (0 silenced).
September 21, 2016 - 01:21:04
Django version 1.9.7, using settings 'sistema_contabil.settings'
Starting development server at http://localhost:8000/
Quit the server with CTRL-BREAK.
HELDER PASTI
Subitem com problemas: [<contato: (27) 999881254>]
[<contato: (27) 999881254>]
Falha na validacao dos objetos: ['', "'list' object has no attribute 'full_clean'", "'list' object has no attribute 'full_clean'"]
Internal Server Error: /entidade/visualizar/5/
Traceback (most recent call last):
  File "C:\Python27\lib\site-packages\django\core\handlers\base.py", line 158, in get_response
    % (callback.__module__, view_name))
ValueError: The view entidade.views.visualizar_entidade didn't return an HttpResponse object. It returned None instead.
Internal Server Error: /entidade/visualizar/5/
Traceback (most recent call last):
  File "C:\Python27\lib\site-packages\django\core\handlers\base.py", line 158, in get_response
    % (callback.__module__, view_name))
ValueError: The view entidade.views.visualizar_entidade didn't return an HttpResponse object. It returned None instead.
[21/Sep/2016 01:22:30] "POST /entidade/visualizar/5/ HTTP/1.1" 500 58089
Performing system checks...

System check identified no issues (0 silenced).
September 21, 2016 - 01:26:21
Django version 1.9.7, using settings 'sistema_contabil.settings'
Starting development server at http://localhost:8000/
Quit the server with CTRL-BREAK.
Olha o que eu quero validar:  HELDER PASTI <class 'entidade.models.entidade'>
HELDER PASTI
Olha o que eu quero validar:  [<contato: (27) 999881254>] <type 'list'>
Subitem com problemas: [<contato: (27) 999881254>]
[<contato: (27) 999881254>]
Olha o que eu quero validar:  localizacao_simples object <class 'entidade.models.localizacao_simples'>
Olha o que eu quero validar:  [] <type 'list'>
Falha na validacao dos objetos: ['', "'list' object has no attribute 'full_clean'", "'list' object has no attribute 'full_clean'"]
Internal Server Error: /entidade/visualizar/5/
Traceback (most recent call last):
  File "C:\Python27\lib\site-packages\django\core\handlers\base.py", line 158, in get_response
    % (callback.__module__, view_name))
ValueError: The view entidade.views.visualizar_entidade didn't return an HttpResponse object. It returned None instead.
Internal Server Error: /entidade/visualizar/5/
Traceback (most recent call last):
  File "C:\Python27\lib\site-packages\django\core\handlers\base.py", line 158, in get_response
    % (callback.__module__, view_name))
ValueError: The view entidade.views.visualizar_entidade didn't return an HttpResponse object. It returned None instead.
[21/Sep/2016 01:26:31] "POST /entidade/visualizar/5/ HTTP/1.1" 500 58089
Performing system checks...

System check identified no issues (0 silenced).
September 21, 2016 - 01:37:15
Django version 1.9.7, using settings 'sistema_contabil.settings'
Starting development server at http://localhost:8000/
Quit the server with CTRL-BREAK.
Olha o que eu quero validar:  HELDER PASTI <class 'entidade.models.entidade'>
HELDER PASTI
Olha o que eu quero validar:  [<contato: (27) 999881254>] <type 'list'>
Subitem com problemas: (27) 999881254
[<contato: (27) 999881254>]
Olha o que eu quero validar:  localizacao_simples object <class 'entidade.models.localizacao_simples'>
Olha o que eu quero validar:  [] <type 'list'>
Falha na validacao dos objetos: ['', '', '']
Internal Server Error: /entidade/visualizar/5/
Traceback (most recent call last):
  File "C:\Python27\lib\site-packages\django\core\handlers\base.py", line 158, in get_response
    % (callback.__module__, view_name))
ValueError: The view entidade.views.visualizar_entidade didn't return an HttpResponse object. It returned None instead.
Internal Server Error: /entidade/visualizar/5/
Traceback (most recent call last):
  File "C:\Python27\lib\site-packages\django\core\handlers\base.py", line 158, in get_response
    % (callback.__module__, view_name))
ValueError: The view entidade.views.visualizar_entidade didn't return an HttpResponse object. It returned None instead.
[21/Sep/2016 01:37:25] "POST /entidade/visualizar/5/ HTTP/1.1" 500 58089
Performing system checks...

System check identified no issues (0 silenced).
September 21, 2016 - 01:38:08
Django version 1.9.7, using settings 'sistema_contabil.settings'
Starting development server at http://localhost:8000/
Quit the server with CTRL-BREAK.
Olha o que eu quero validar:  HELDER PASTI <class 'entidade.models.entidade'>
HELDER PASTI
Olha o que eu quero validar:  [<contato: (27) 999881254>] <type 'list'>
Subitem com problemas: (27) 999881254
[<contato: (27) 999881254>]
Olha o que eu quero validar:  localizacao_simples object <class 'entidade.models.localizacao_simples'>
Olha o que eu quero validar:  [] <type 'list'>
Falha na validacao dos objetos: ['', '', '']
Internal Server Error: /entidade/visualizar/5/
Traceback (most recent call last):
  File "C:\Python27\lib\site-packages\django\core\handlers\base.py", line 158, in get_response
    % (callback.__module__, view_name))
ValueError: The view entidade.views.visualizar_entidade didn't return an HttpResponse object. It returned None instead.
Internal Server Error: /entidade/visualizar/5/
Traceback (most recent call last):
  File "C:\Python27\lib\site-packages\django\core\handlers\base.py", line 158, in get_response
    % (callback.__module__, view_name))
ValueError: The view entidade.views.visualizar_entidade didn't return an HttpResponse object. It returned None instead.
[21/Sep/2016 01:38:10] "POST /entidade/visualizar/5/ HTTP/1.1" 500 58089
Performing system checks...

System check identified no issues (0 silenced).
September 21, 2016 - 01:39:07
Django version 1.9.7, using settings 'sistema_contabil.settings'
Starting development server at http://localhost:8000/
Quit the server with CTRL-BREAK.
Olha o que eu quero validar:  HELDER PASTI <class 'entidade.models.entidade'>
o erro:
HELDER PASTI
Olha o que eu quero validar:  [<contato: (27) 999881254>] <type 'list'>
o erro:
Subitem com problemas: (27) 999881254
[<contato: (27) 999881254>]
Olha o que eu quero validar:  localizacao_simples object <class 'entidade.models.localizacao_simples'>
Olha o que eu quero validar:  [] <type 'list'>
Falha na validacao dos objetos: ['', '', '']
Internal Server Error: /entidade/visualizar/5/
Traceback (most recent call last):
  File "C:\Python27\lib\site-packages\django\core\handlers\base.py", line 158, in get_response
    % (callback.__module__, view_name))
ValueError: The view entidade.views.visualizar_entidade didn't return an HttpResponse object. It returned None instead.
Internal Server Error: /entidade/visualizar/5/
Traceback (most recent call last):
  File "C:\Python27\lib\site-packages\django\core\handlers\base.py", line 158, in get_response
    % (callback.__module__, view_name))
ValueError: The view entidade.views.visualizar_entidade didn't return an HttpResponse object. It returned None instead.
[21/Sep/2016 01:39:09] "POST /entidade/visualizar/5/ HTTP/1.1" 500 58089
Performing system checks...

System check identified no issues (0 silenced).
September 21, 2016 - 01:41:14
Django version 1.9.7, using settings 'sistema_contabil.settings'
Starting development server at http://localhost:8000/
Quit the server with CTRL-BREAK.
Olha o que eu quero validar:  HELDER PASTI <class 'entidade.models.entidade'>
Internal Server Error: /entidade/visualizar/5/
Traceback (most recent call last):
  File "C:\Python27\lib\site-packages\django\core\handlers\base.py", line 149, in get_response
    response = self.process_exception_by_middleware(e, request)
  File "C:\Python27\lib\site-packages\django\core\handlers\base.py", line 147, in get_response
    response = wrapped_callback(request, *callback_args, **callback_kwargs)
  File "C:\Users\diego\OneDrive\Projetos\sistema_contabil\entidade\views.py", line 508, in visualizar_entidade
    validacao_dados,erros = validar_objetos_formulario(lista_objetos)
  File "C:\Users\diego\OneDrive\Projetos\sistema_contabil\entidade\views.py", line 648, in validar_objetos_formulario
    resultado, mensagem = validar_objeto(item)
  File "C:\Users\diego\OneDrive\Projetos\sistema_contabil\entidade\views.py", line 664, in validar_objeto
    registro.full_clean()
  File "C:\Python27\lib\site-packages\django\db\models\base.py", line 1144, in full_clean
    raise ValidationError(errors)
ValidationError: {'tipo_vencimento_iss': [u'Este campo n\xe3o pode estar vazio.'], 'taxa_iss': [u'Este campo n\xe3o pode estar vazio.'], 'natureza_juridica': [u'Este campo n\xe3o pode estar vazio.'], 'endereco': [u'A inst\xe2ncia de localizacao_simples com id 0 n\xe3o existe.'], 'dia_vencimento_iss': [u'Este campo n\xe3o pode estar vazio.'], 'numero_filiais': [u'Este campo n\xe3o pode estar vazio.'], 'cpf_cnpj': [u'Entidade com este Cnpj: j\xe1 existe.']}
Internal Server Error: /entidade/visualizar/5/
Traceback (most recent call last):
  File "C:\Python27\lib\site-packages\django\core\handlers\base.py", line 149, in get_response
    response = self.process_exception_by_middleware(e, request)
  File "C:\Python27\lib\site-packages\django\core\handlers\base.py", line 147, in get_response
    response = wrapped_callback(request, *callback_args, **callback_kwargs)
  File "C:\Users\diego\OneDrive\Projetos\sistema_contabil\entidade\views.py", line 508, in visualizar_entidade
    validacao_dados,erros = validar_objetos_formulario(lista_objetos)
  File "C:\Users\diego\OneDrive\Projetos\sistema_contabil\entidade\views.py", line 648, in validar_objetos_formulario
    resultado, mensagem = validar_objeto(item)
  File "C:\Users\diego\OneDrive\Projetos\sistema_contabil\entidade\views.py", line 664, in validar_objeto
    registro.full_clean()
  File "C:\Python27\lib\site-packages\django\db\models\base.py", line 1144, in full_clean
    raise ValidationError(errors)
ValidationError: {'tipo_vencimento_iss': [u'Este campo n\xe3o pode estar vazio.'], 'taxa_iss': [u'Este campo n\xe3o pode estar vazio.'], 'natureza_juridica': [u'Este campo n\xe3o pode estar vazio.'], 'endereco': [u'A inst\xe2ncia de localizacao_simples com id 0 n\xe3o existe.'], 'dia_vencimento_iss': [u'Este campo n\xe3o pode estar vazio.'], 'numero_filiais': [u'Este campo n\xe3o pode estar vazio.'], 'cpf_cnpj': [u'Entidade com este Cnpj: j\xe1 existe.']}
[21/Sep/2016 01:41:15] "POST /entidade/visualizar/5/ HTTP/1.1" 500 84272
Performing system checks...

System check identified no issues (0 silenced).
September 21, 2016 - 01:43:21
Django version 1.9.7, using settings 'sistema_contabil.settings'
Starting development server at http://localhost:8000/
Quit the server with CTRL-BREAK.
Olha o que eu quero validar:  HELDER PASTI <class 'entidade.models.entidade'>
o erro:
HELDER PASTI
Olha o que eu quero validar:  [<contato: (27) 999881254>] <type 'list'>
o erro:
Subitem com problemas: (27) 999881254
[<contato: (27) 999881254>]
Olha o que eu quero validar:  localizacao_simples object <class 'entidade.models.localizacao_simples'>
Olha o que eu quero validar:  [] <type 'list'>
Falha na validacao dos objetos: ['', '', '']
Internal Server Error: /entidade/visualizar/5/
Traceback (most recent call last):
  File "C:\Python27\lib\site-packages\django\core\handlers\base.py", line 158, in get_response
    % (callback.__module__, view_name))
ValueError: The view entidade.views.visualizar_entidade didn't return an HttpResponse object. It returned None instead.
Internal Server Error: /entidade/visualizar/5/
Traceback (most recent call last):
  File "C:\Python27\lib\site-packages\django\core\handlers\base.py", line 158, in get_response
    % (callback.__module__, view_name))
ValueError: The view entidade.views.visualizar_entidade didn't return an HttpResponse object. It returned None instead.
[21/Sep/2016 01:43:24] "POST /entidade/visualizar/5/ HTTP/1.1" 500 58089
Performing system checks...

System check identified no issues (0 silenced).
September 21, 2016 - 01:43:59
Django version 1.9.7, using settings 'sistema_contabil.settings'
Starting development server at http://localhost:8000/
Quit the server with CTRL-BREAK.
Olha o que eu quero validar:  HELDER PASTI <class 'entidade.models.entidade'>
Internal Server Error: /entidade/visualizar/5/
Traceback (most recent call last):
  File "C:\Python27\lib\site-packages\django\core\handlers\base.py", line 149, in get_response
    response = self.process_exception_by_middleware(e, request)
  File "C:\Python27\lib\site-packages\django\core\handlers\base.py", line 147, in get_response
    response = wrapped_callback(request, *callback_args, **callback_kwargs)
  File "C:\Users\diego\OneDrive\Projetos\sistema_contabil\entidade\views.py", line 508, in visualizar_entidade
    validacao_dados,erros = validar_objetos_formulario(lista_objetos)
  File "C:\Users\diego\OneDrive\Projetos\sistema_contabil\entidade\views.py", line 648, in validar_objetos_formulario
    resultado, mensagem = validar_objeto(item)
  File "C:\Users\diego\OneDrive\Projetos\sistema_contabil\entidade\views.py", line 664, in validar_objeto
    registro.full_clean()
  File "C:\Python27\lib\site-packages\django\db\models\base.py", line 1144, in full_clean
    raise ValidationError(errors)
ValidationError: {'tipo_vencimento_iss': [u'Este campo n\xe3o pode estar vazio.'], 'taxa_iss': [u'Este campo n\xe3o pode estar vazio.'], 'natureza_juridica': [u'Este campo n\xe3o pode estar vazio.'], 'endereco': [u'A inst\xe2ncia de localizacao_simples com id 0 n\xe3o existe.'], 'dia_vencimento_iss': [u'Este campo n\xe3o pode estar vazio.'], 'numero_filiais': [u'Este campo n\xe3o pode estar vazio.'], 'cpf_cnpj': [u'Entidade com este Cnpj: j\xe1 existe.']}
Internal Server Error: /entidade/visualizar/5/
Traceback (most recent call last):
  File "C:\Python27\lib\site-packages\django\core\handlers\base.py", line 149, in get_response
    response = self.process_exception_by_middleware(e, request)
  File "C:\Python27\lib\site-packages\django\core\handlers\base.py", line 147, in get_response
    response = wrapped_callback(request, *callback_args, **callback_kwargs)
  File "C:\Users\diego\OneDrive\Projetos\sistema_contabil\entidade\views.py", line 508, in visualizar_entidade
    validacao_dados,erros = validar_objetos_formulario(lista_objetos)
  File "C:\Users\diego\OneDrive\Projetos\sistema_contabil\entidade\views.py", line 648, in validar_objetos_formulario
    resultado, mensagem = validar_objeto(item)
  File "C:\Users\diego\OneDrive\Projetos\sistema_contabil\entidade\views.py", line 664, in validar_objeto
    registro.full_clean()
  File "C:\Python27\lib\site-packages\django\db\models\base.py", line 1144, in full_clean
    raise ValidationError(errors)
ValidationError: {'tipo_vencimento_iss': [u'Este campo n\xe3o pode estar vazio.'], 'taxa_iss': [u'Este campo n\xe3o pode estar vazio.'], 'natureza_juridica': [u'Este campo n\xe3o pode estar vazio.'], 'endereco': [u'A inst\xe2ncia de localizacao_simples com id 0 n\xe3o existe.'], 'dia_vencimento_iss': [u'Este campo n\xe3o pode estar vazio.'], 'numero_filiais': [u'Este campo n\xe3o pode estar vazio.'], 'cpf_cnpj': [u'Entidade com este Cnpj: j\xe1 existe.']}
[21/Sep/2016 01:44:00] "POST /entidade/visualizar/5/ HTTP/1.1" 500 84278
Performing system checks...

System check identified no issues (0 silenced).
September 21, 2016 - 01:48:58
Django version 1.9.7, using settings 'sistema_contabil.settings'
Starting development server at http://localhost:8000/
Quit the server with CTRL-BREAK.
Olha o que eu quero validar:  HELDER PASTI <class 'entidade.models.entidade'>
Internal Server Error: /entidade/visualizar/5/
Traceback (most recent call last):
  File "C:\Python27\lib\site-packages\django\core\handlers\base.py", line 149, in get_response
    response = self.process_exception_by_middleware(e, request)
  File "C:\Python27\lib\site-packages\django\core\handlers\base.py", line 147, in get_response
    response = wrapped_callback(request, *callback_args, **callback_kwargs)
  File "C:\Users\diego\OneDrive\Projetos\sistema_contabil\entidade\views.py", line 508, in visualizar_entidade
    validacao_dados,erros = validar_objetos_formulario(lista_objetos)
  File "C:\Users\diego\OneDrive\Projetos\sistema_contabil\entidade\views.py", line 648, in validar_objetos_formulario
    resultado, mensagem = validar_objeto(item)
  File "C:\Users\diego\OneDrive\Projetos\sistema_contabil\entidade\views.py", line 664, in validar_objeto
    registro.full_clean()
  File "C:\Python27\lib\site-packages\django\db\models\base.py", line 1144, in full_clean
    raise ValidationError(errors)
ValidationError: {'taxa_iss': [u'Este campo n\xe3o pode estar vazio.'], 'natureza_juridica': [u'Este campo n\xe3o pode estar vazio.'], 'endereco': [u'A inst\xe2ncia de localizacao_simples com id 0 n\xe3o existe.'], 'dia_vencimento_iss': [u'Este campo n\xe3o pode estar vazio.'], 'numero_filiais': [u'Este campo n\xe3o pode estar vazio.'], 'cpf_cnpj': [u'Entidade com este Cnpj: j\xe1 existe.']}
Internal Server Error: /entidade/visualizar/5/
Traceback (most recent call last):
  File "C:\Python27\lib\site-packages\django\core\handlers\base.py", line 149, in get_response
    response = self.process_exception_by_middleware(e, request)
  File "C:\Python27\lib\site-packages\django\core\handlers\base.py", line 147, in get_response
    response = wrapped_callback(request, *callback_args, **callback_kwargs)
  File "C:\Users\diego\OneDrive\Projetos\sistema_contabil\entidade\views.py", line 508, in visualizar_entidade
    validacao_dados,erros = validar_objetos_formulario(lista_objetos)
  File "C:\Users\diego\OneDrive\Projetos\sistema_contabil\entidade\views.py", line 648, in validar_objetos_formulario
    resultado, mensagem = validar_objeto(item)
  File "C:\Users\diego\OneDrive\Projetos\sistema_contabil\entidade\views.py", line 664, in validar_objeto
    registro.full_clean()
  File "C:\Python27\lib\site-packages\django\db\models\base.py", line 1144, in full_clean
    raise ValidationError(errors)
ValidationError: {'taxa_iss': [u'Este campo n\xe3o pode estar vazio.'], 'natureza_juridica': [u'Este campo n\xe3o pode estar vazio.'], 'endereco': [u'A inst\xe2ncia de localizacao_simples com id 0 n\xe3o existe.'], 'dia_vencimento_iss': [u'Este campo n\xe3o pode estar vazio.'], 'numero_filiais': [u'Este campo n\xe3o pode estar vazio.'], 'cpf_cnpj': [u'Entidade com este Cnpj: j\xe1 existe.']}
[21/Sep/2016 01:49:01] "POST /entidade/visualizar/5/ HTTP/1.1" 500 83662
Performing system checks...

System check identified no issues (0 silenced).
September 21, 2016 - 01:49:28
Django version 1.9.7, using settings 'sistema_contabil.settings'
Starting development server at http://localhost:8000/
Quit the server with CTRL-BREAK.
Olha o que eu quero validar:  HELDER PASTI <class 'entidade.models.entidade'>
Internal Server Error: /entidade/visualizar/5/
Traceback (most recent call last):
  File "C:\Python27\lib\site-packages\django\core\handlers\base.py", line 149, in get_response
    response = self.process_exception_by_middleware(e, request)
  File "C:\Python27\lib\site-packages\django\core\handlers\base.py", line 147, in get_response
    response = wrapped_callback(request, *callback_args, **callback_kwargs)
  File "C:\Users\diego\OneDrive\Projetos\sistema_contabil\entidade\views.py", line 508, in visualizar_entidade
    validacao_dados,erros = validar_objetos_formulario(lista_objetos)
  File "C:\Users\diego\OneDrive\Projetos\sistema_contabil\entidade\views.py", line 648, in validar_objetos_formulario
    resultado, mensagem = validar_objeto(item)
  File "C:\Users\diego\OneDrive\Projetos\sistema_contabil\entidade\views.py", line 664, in validar_objeto
    registro.full_clean()
  File "C:\Python27\lib\site-packages\django\db\models\base.py", line 1144, in full_clean
    raise ValidationError(errors)
ValidationError: {'endereco': [u'A inst\xe2ncia de localizacao_simples com id 0 n\xe3o existe.'], 'numero_filiais': [u'Este campo n\xe3o pode estar vazio.'], 'natureza_juridica': [u'Este campo n\xe3o pode estar vazio.'], 'cpf_cnpj': [u'Entidade com este Cnpj: j\xe1 existe.']}
Internal Server Error: /entidade/visualizar/5/
Traceback (most recent call last):
  File "C:\Python27\lib\site-packages\django\core\handlers\base.py", line 149, in get_response
    response = self.process_exception_by_middleware(e, request)
  File "C:\Python27\lib\site-packages\django\core\handlers\base.py", line 147, in get_response
    response = wrapped_callback(request, *callback_args, **callback_kwargs)
  File "C:\Users\diego\OneDrive\Projetos\sistema_contabil\entidade\views.py", line 508, in visualizar_entidade
    validacao_dados,erros = validar_objetos_formulario(lista_objetos)
  File "C:\Users\diego\OneDrive\Projetos\sistema_contabil\entidade\views.py", line 648, in validar_objetos_formulario
    resultado, mensagem = validar_objeto(item)
  File "C:\Users\diego\OneDrive\Projetos\sistema_contabil\entidade\views.py", line 664, in validar_objeto
    registro.full_clean()
  File "C:\Python27\lib\site-packages\django\db\models\base.py", line 1144, in full_clean
    raise ValidationError(errors)
ValidationError: {'endereco': [u'A inst\xe2ncia de localizacao_simples com id 0 n\xe3o existe.'], 'numero_filiais': [u'Este campo n\xe3o pode estar vazio.'], 'natureza_juridica': [u'Este campo n\xe3o pode estar vazio.'], 'cpf_cnpj': [u'Entidade com este Cnpj: j\xe1 existe.']}
[21/Sep/2016 01:49:33] "POST /entidade/visualizar/5/ HTTP/1.1" 500 82518
Unhandled exception in thread started by <function wrapper at 0x03A9A8B0>
Traceback (most recent call last):
  File "C:\Python27\lib\site-packages\django\utils\autoreload.py", line 226, in wrapper
    fn(*args, **kwargs)
  File "C:\Python27\lib\site-packages\django\core\management\commands\runserver.py", line 109, in inner_run
    autoreload.raise_last_exception()
  File "C:\Python27\lib\site-packages\django\utils\autoreload.py", line 249, in raise_last_exception
    six.reraise(*_exception)
  File "C:\Python27\lib\site-packages\django\utils\autoreload.py", line 226, in wrapper
    fn(*args, **kwargs)
  File "C:\Python27\lib\site-packages\django\__init__.py", line 18, in setup
    apps.populate(settings.INSTALLED_APPS)
  File "C:\Python27\lib\site-packages\django\apps\registry.py", line 108, in populate
    app_config.import_models(all_models)
  File "C:\Python27\lib\site-packages\django\apps\config.py", line 202, in import_models
    self.models_module = import_module(models_module_name)
  File "C:\Python27\lib\importlib\__init__.py", line 37, in import_module
    __import__(name)
  File "C:\Users\diego\OneDrive\Projetos\sistema_contabil\entidade\models.py", line 69
    numero_filiais = models.IntegerField("Numero Filiais", null=True,,blank=True, default=0)
                                                                     ^
SyntaxError: invalid syntax
Performing system checks...

System check identified no issues (0 silenced).
September 21, 2016 - 01:50:17
Django version 1.9.7, using settings 'sistema_contabil.settings'
Starting development server at http://localhost:8000/
Quit the server with CTRL-BREAK.
Performing system checks...

System check identified no issues (0 silenced).
September 21, 2016 - 01:51:11
Django version 1.9.7, using settings 'sistema_contabil.settings'
Starting development server at http://localhost:8000/
Quit the server with CTRL-BREAK.
Olha o que eu quero validar:  HELDER PASTI <class 'entidade.models.entidade'>
Internal Server Error: /entidade/visualizar/5/
Traceback (most recent call last):
  File "C:\Python27\lib\site-packages\django\core\handlers\base.py", line 149, in get_response
    response = self.process_exception_by_middleware(e, request)
  File "C:\Python27\lib\site-packages\django\core\handlers\base.py", line 147, in get_response
    response = wrapped_callback(request, *callback_args, **callback_kwargs)
  File "C:\Users\diego\OneDrive\Projetos\sistema_contabil\entidade\views.py", line 508, in visualizar_entidade
    validacao_dados,erros = validar_objetos_formulario(lista_objetos)
  File "C:\Users\diego\OneDrive\Projetos\sistema_contabil\entidade\views.py", line 648, in validar_objetos_formulario
    resultado, mensagem = validar_objeto(item)
  File "C:\Users\diego\OneDrive\Projetos\sistema_contabil\entidade\views.py", line 664, in validar_objeto
    registro.full_clean()
  File "C:\Python27\lib\site-packages\django\db\models\base.py", line 1144, in full_clean
    raise ValidationError(errors)
ValidationError: {'endereco': [u'A inst\xe2ncia de localizacao_simples com id 0 n\xe3o existe.'], 'cpf_cnpj': [u'Entidade com este Cnpj: j\xe1 existe.']}
Internal Server Error: /entidade/visualizar/5/
Traceback (most recent call last):
  File "C:\Python27\lib\site-packages\django\core\handlers\base.py", line 149, in get_response
    response = self.process_exception_by_middleware(e, request)
  File "C:\Python27\lib\site-packages\django\core\handlers\base.py", line 147, in get_response
    response = wrapped_callback(request, *callback_args, **callback_kwargs)
  File "C:\Users\diego\OneDrive\Projetos\sistema_contabil\entidade\views.py", line 508, in visualizar_entidade
    validacao_dados,erros = validar_objetos_formulario(lista_objetos)
  File "C:\Users\diego\OneDrive\Projetos\sistema_contabil\entidade\views.py", line 648, in validar_objetos_formulario
    resultado, mensagem = validar_objeto(item)
  File "C:\Users\diego\OneDrive\Projetos\sistema_contabil\entidade\views.py", line 664, in validar_objeto
    registro.full_clean()
  File "C:\Python27\lib\site-packages\django\db\models\base.py", line 1144, in full_clean
    raise ValidationError(errors)
ValidationError: {'endereco': [u'A inst\xe2ncia de localizacao_simples com id 0 n\xe3o existe.'], 'cpf_cnpj': [u'Entidade com este Cnpj: j\xe1 existe.']}
[21/Sep/2016 01:51:14] "POST /entidade/visualizar/5/ HTTP/1.1" 500 81329
Performing system checks...

System check identified no issues (0 silenced).
September 21, 2016 - 01:51:32
Django version 1.9.7, using settings 'sistema_contabil.settings'
Starting development server at http://localhost:8000/
Quit the server with CTRL-BREAK.
Olha o que eu quero validar:  HELDER PASTI <class 'entidade.models.entidade'>
o erro:
HELDER PASTI
Olha o que eu quero validar:  [<contato: (27) 999881254>] <type 'list'>
o erro:
Subitem com problemas: (27) 999881254
[<contato: (27) 999881254>]
Olha o que eu quero validar:  localizacao_simples object Internal Server Error: /entidade/visualizar/5/
Traceback (most recent call last):
  File "C:\Python27\lib\site-packages\django\core\handlers\base.py", line 158, in get_response
    % (callback.__module__, view_name))
ValueError: The view entidade.views.visualizar_entidade didn't return an HttpResponse object. It returned None instead.
Internal Server Error: /entidade/visualizar/5/
Traceback (most recent call last):
  File "C:\Python27\lib\site-packages\django\core\handlers\base.py", line 158, in get_response
    % (callback.__module__, view_name))
ValueError: The view entidade.views.visualizar_entidade didn't return an HttpResponse object. It returned None instead.
<class 'entidade.models.localizacao_simples'>
Olha o que eu quero validar:  [] <type 'list'>
Falha na validacao dos objetos: ['', '', '']
[21/Sep/2016 01:51:34] "POST /entidade/visualizar/5/ HTTP/1.1" 500 58089
Performing system checks...

System check identified no issues (0 silenced).
September 21, 2016 - 01:54:36
Django version 1.9.7, using settings 'sistema_contabil.settings'
Starting development server at http://localhost:8000/
Quit the server with CTRL-BREAK.
Olha o que eu quero validar:  HELDER PASTI <class 'entidade.models.entidade'>
<class 'django.core.exceptions.ValidationError'>
({'endereco': [ValidationError([u'A inst\xe2ncia de localizacao_simples com id 0 n\xe3o existe.'])], 'cpf_cnpj': [ValidationError([u'Entidade com este Cnpj: j\xe1 existe.'])]}, None, None)
{'endereco': [u'A inst\xe2ncia de localizacao_simples com id 0 n\xe3o existe.'], 'cpf_cnpj': [u'Entidade com este Cnpj: j\xe1 existe.']}
Internal Server Error: /entidade/visualizar/5/
Traceback (most recent call last):
  File "C:\Python27\lib\site-packages\django\core\handlers\base.py", line 149, in get_response
    response = self.process_exception_by_middleware(e, request)
  File "C:\Python27\lib\site-packages\django\core\handlers\base.py", line 147, in get_response
    response = wrapped_callback(request, *callback_args, **callback_kwargs)
  File "C:\Users\diego\OneDrive\Projetos\sistema_contabil\entidade\views.py", line 508, in visualizar_entidade
    validacao_dados,erros = validar_objetos_formulario(lista_objetos)
  File "C:\Users\diego\OneDrive\Projetos\sistema_contabil\entidade\views.py", line 648, in validar_objetos_formulario
    resultado, mensagem = validar_objeto(item)
  File "C:\Users\diego\OneDrive\Projetos\sistema_contabil\entidade\views.py", line 673, in validar_objeto
    x, y = excecao.args  # unpack args
ValueError: too many values to unpack
Internal Server Error: /entidade/visualizar/5/
Traceback (most recent call last):
  File "C:\Python27\lib\site-packages\django\core\handlers\base.py", line 149, in get_response
    response = self.process_exception_by_middleware(e, request)
  File "C:\Python27\lib\site-packages\django\core\handlers\base.py", line 147, in get_response
    response = wrapped_callback(request, *callback_args, **callback_kwargs)
  File "C:\Users\diego\OneDrive\Projetos\sistema_contabil\entidade\views.py", line 508, in visualizar_entidade
    validacao_dados,erros = validar_objetos_formulario(lista_objetos)
  File "C:\Users\diego\OneDrive\Projetos\sistema_contabil\entidade\views.py", line 648, in validar_objetos_formulario
    resultado, mensagem = validar_objeto(item)
  File "C:\Users\diego\OneDrive\Projetos\sistema_contabil\entidade\views.py", line 673, in validar_objeto
    x, y = excecao.args  # unpack args
ValueError: too many values to unpack
[21/Sep/2016 01:54:42] "POST /entidade/visualizar/5/ HTTP/1.1" 500 76171
Performing system checks...

System check identified no issues (0 silenced).
September 21, 2016 - 01:55:53
Django version 1.9.7, using settings 'sistema_contabil.settings'
Starting development server at http://localhost:8000/
Quit the server with CTRL-BREAK.
Olha o que eu quero validar:  HELDER PASTI <class 'entidade.models.entidade'>
<class 'django.core.exceptions.ValidationError'>
({'endereco': [ValidationError([u'A inst\xe2ncia de localizacao_simples com id 0 n\xe3o existe.'])], 'cpf_cnpj': [ValidationError([u'Entidade com este Cnpj: j\xe1 existe.'])]}, None, None)
{'endereco': [u'A inst\xe2ncia de localizacao_simples com id 0 n\xe3o existe.'], 'cpf_cnpj': [u'Entidade com este Cnpj: j\xe1 existe.']}
o erro:
HELDER PASTI
Olha o que eu quero validar:  [<contato: (27) 999881254>] <type 'list'>
<class 'django.core.exceptions.ValidationError'>
({'entidade': [ValidationError([u'Este campo n\xe3o pode ser nulo.'])], 'tipo_contato': [ValidationError([u"Valor u'CELULAR' n\xe3o \xe9 uma op\xe7\xe3o v\xe1lida."])], 'email': [ValidationError([u'Formato Inv\xe1lido!'])]}, None, None)
{'entidade': [u'Este campo n\xe3o pode ser nulo.'], 'tipo_contato': [u"Valor u'CELULAR' n\xe3o \xe9 uma op\xe7\xe3o v\xe1lida."], 'email': [u'Formato Inv\xe1lido!']}
o erro:
Subitem com problemas: (27) 999881254
[<contato: (27) 999881254>]
Olha o que eu quero validar:  localizacao_simples object <class 'entidade.models.localizacao_simples'>
Olha o que eu quero validar:  [] <type 'list'>
Falha na validacao dos objetos: ['', '', '']
Internal Server Error: /entidade/visualizar/5/
Traceback (most recent call last):
  File "C:\Python27\lib\site-packages\django\core\handlers\base.py", line 158, in get_response
    % (callback.__module__, view_name))
ValueError: The view entidade.views.visualizar_entidade didn't return an HttpResponse object. It returned None instead.
Internal Server Error: /entidade/visualizar/5/
Traceback (most recent call last):
  File "C:\Python27\lib\site-packages\django\core\handlers\base.py", line 158, in get_response
    % (callback.__module__, view_name))
ValueError: The view entidade.views.visualizar_entidade didn't return an HttpResponse object. It returned None instead.
[21/Sep/2016 01:55:55] "POST /entidade/visualizar/5/ HTTP/1.1" 500 58089
Performing system checks...

System check identified no issues (0 silenced).
September 21, 2016 - 01:56:50
Django version 1.9.7, using settings 'sistema_contabil.settings'
Starting development server at http://localhost:8000/
Quit the server with CTRL-BREAK.
Olha o que eu quero validar:  HELDER PASTI <class 'entidade.models.entidade'>
o erro: {'endereco': [u'A inst\xe2ncia de localizacao_simples com id 0 n\xe3o existe.'], 'cpf_cnpj': [u'Entidade com este Cnpj: j\xe1 existe.']}
HELDER PASTI
Olha o que eu quero validar:  [<contato: (27) 999881254>] <type 'list'>
o erro: {'entidade': [u'Este campo n\xe3o pode ser nulo.'], 'tipo_contato': [u"Valor u'CELULAR' n\xe3o \xe9 uma op\xe7\xe3o v\xe1lida."], 'email': [u'Formato Inv\xe1lido!']}
Subitem com problemas: (27) 999881254 {'entidade': [u'Este campo n\xe3o pode ser nulo.'], 'tipo_contato': [u"Valor u'CELULAR' n\xe3o \xe9 uma op\xe7\xe3o v\xe1lida."], 'email': [u'Formato Inv\xe1lido!']}
[<contato: (27) 999881254>]
Olha o que eu quero validar:  localizacao_simples object <class 'entidade.models.localizacao_simples'>
Olha o que eu quero validar:  [] <type 'list'>
Falha na validacao dos objetos: [ValidationError({'endereco': [u'A inst\xe2ncia de localizacao_simples com id 0 n\xe3o existe.'], 'cpf_cnpj': [u'Entidade com este Cnpj: j\xe1 existe.']}), ValidationError({'entidade': [u'Este campo n\xe3o pode ser nulo.'], 'tipo_contato': [u"Valor u'CELULAR' n\xe3o \xe9 uma op\xe7\xe3o v\xe1lida."], 'email': [u'Formato Inv\xe1lido!']}), ValidationError({'entidade': [u'Este campo n\xe3o pode ser nulo.'], 'tipo_contato': [u"Valor u'CELULAR' n\xe3o \xe9 uma op\xe7\xe3o v\xe1lida."], 'email': [u'Formato Inv\xe1lido!']})]
Internal Server Error: /entidade/visualizar/5/
Traceback (most recent call last):
  File "C:\Python27\lib\site-packages\django\core\handlers\base.py", line 158, in get_response
    % (callback.__module__, view_name))
ValueError: The view entidade.views.visualizar_entidade didn't return an HttpResponse object. It returned None instead.
Internal Server Error: /entidade/visualizar/5/
Traceback (most recent call last):
  File "C:\Python27\lib\site-packages\django\core\handlers\base.py", line 158, in get_response
    % (callback.__module__, view_name))
ValueError: The view entidade.views.visualizar_entidade didn't return an HttpResponse object. It returned None instead.
[21/Sep/2016 01:56:51] "POST /entidade/visualizar/5/ HTTP/1.1" 500 58089
Performing system checks...

System check identified no issues (0 silenced).
September 21, 2016 - 01:58:15
Django version 1.9.7, using settings 'sistema_contabil.settings'
Starting development server at http://localhost:8000/
Quit the server with CTRL-BREAK.
Olha o que eu quero validar:  HELDER PASTI <class 'entidade.models.entidade'>
o erro: {'endereco': [u'A inst\xe2ncia de localizacao_simples com id 0 n\xe3o existe.'], 'cpf_cnpj': [u'Entidade com este Cnpj: j\xe1 existe.']}
HELDER PASTI
Olha o que eu quero validar:  [<contato: (27) 999881254>] <type 'list'>
o erro: {'entidade': [u'Este campo n\xe3o pode ser nulo.'], 'tipo_contato': [u"Valor u'CELULAR' n\xe3o \xe9 uma op\xe7\xe3o v\xe1lida."], 'email': [u'Formato Inv\xe1lido!']}
Subitem com problemas: (27) 999881254 {'entidade': [u'Este campo n\xe3o pode ser nulo.'], 'tipo_contato': [u"Valor u'CELULAR' n\xe3o \xe9 uma op\xe7\xe3o v\xe1lida."], 'email': [u'Formato Inv\xe1lido!']}
[<contato: (27) 999881254>]
Olha o que eu quero validar:  localizacao_simples object <class 'entidade.models.localizacao_simples'>
Olha o que eu quero validar:  [] <type 'list'>
Falha na validacao dos objetos: [ValidationError({'endereco': [u'A inst\xe2ncia de localizacao_simples com id 0 n\xe3o existe.'], 'cpf_cnpj': [u'Entidade com este Cnpj: j\xe1 existe.']}), ValidationError({'entidade': [u'Este campo n\xe3o pode ser nulo.'], 'tipo_contato': [u"Valor u'CELULAR' n\xe3o \xe9 uma op\xe7\xe3o v\xe1lida."], 'email': [u'Formato Inv\xe1lido!']}), ValidationError({'entidade': [u'Este campo n\xe3o pode ser nulo.'], 'tipo_contato': [u"Valor u'CELULAR' n\xe3o \xe9 uma op\xe7\xe3o v\xe1lida."], 'email': [u'Formato Inv\xe1lido!']})]
Internal Server Error: /entidade/visualizar/5/
Traceback (most recent call last):
  File "C:\Python27\lib\site-packages\django\core\handlers\base.py", line 158, in get_response
    % (callback.__module__, view_name))
ValueError: The view entidade.views.visualizar_entidade didn't return an HttpResponse object. It returned None instead.
Internal Server Error: /entidade/visualizar/5/
Traceback (most recent call last):
  File "C:\Python27\lib\site-packages\django\core\handlers\base.py", line 158, in get_response
    % (callback.__module__, view_name))
ValueError: The view entidade.views.visualizar_entidade didn't return an HttpResponse object. It returned None instead.
[21/Sep/2016 01:58:19] "POST /entidade/visualizar/5/ HTTP/1.1" 500 58089
Performing system checks...

System check identified no issues (0 silenced).
September 21, 2016 - 01:58:55
Django version 1.9.7, using settings 'sistema_contabil.settings'
Starting development server at http://localhost:8000/
Quit the server with CTRL-BREAK.
Olha o que eu quero validar:  HELDER PASTI <class 'entidade.models.entidade'>
o erro: ['endereco', 'cpf_cnpj']
HELDER PASTI
Olha o que eu quero validar:  [<contato: (27) 999881254>] <type 'list'>
o erro: ['entidade', 'tipo_contato', 'email']
Subitem com problemas: (27) 999881254 {'entidade': [u'Este campo n\xe3o pode ser nulo.'], 'tipo_contato': [u"Valor u'CELULAR' n\xe3o \xe9 uma op\xe7\xe3o v\xe1lida."], 'email': [u'Formato Inv\xe1lido!']}
[<contato: (27) 999881254>]
Olha o que eu quero validar:  localizacao_simples object <class 'entidade.models.localizacao_simples'>
Olha o que eu quero validar:  [] <type 'list'>
Falha na validacao dos objetos: [ValidationError({'endereco': [u'A inst\xe2ncia de localizacao_simples com id 0 n\xe3o existe.'], 'cpf_cnpj': [u'Entidade com este Cnpj: j\xe1 existe.']}), ValidationError({'entidade': [u'Este campo n\xe3o pode ser nulo.'], 'tipo_contato': [u"Valor u'CELULAR' n\xe3o \xe9 uma op\xe7\xe3o v\xe1lida."], 'email': [u'Formato Inv\xe1lido!']}), ValidationError({'entidade': [u'Este campo n\xe3o pode ser nulo.'], 'tipo_contato': [u"Valor u'CELULAR' n\xe3o \xe9 uma op\xe7\xe3o v\xe1lida."], 'email': [u'Formato Inv\xe1lido!']})]
Internal Server Error: /entidade/visualizar/5/
Traceback (most recent call last):
  File "C:\Python27\lib\site-packages\django\core\handlers\base.py", line 158, in get_response
    % (callback.__module__, view_name))
ValueError: The view entidade.views.visualizar_entidade didn't return an HttpResponse object. It returned None instead.
Internal Server Error: /entidade/visualizar/5/
Traceback (most recent call last):
  File "C:\Python27\lib\site-packages\django\core\handlers\base.py", line 158, in get_response
    % (callback.__module__, view_name))
ValueError: The view entidade.views.visualizar_entidade didn't return an HttpResponse object. It returned None instead.
[21/Sep/2016 01:58:57] "POST /entidade/visualizar/5/ HTTP/1.1" 500 58089
Performing system checks...

System check identified no issues (0 silenced).
September 21, 2016 - 01:59:42
Django version 1.9.7, using settings 'sistema_contabil.settings'
Starting development server at http://localhost:8000/
Quit the server with CTRL-BREAK.
Olha o que eu quero validar:  HELDER PASTI <class 'entidade.models.entidade'>
Veja o problema: endereco
Veja o problema: cpf_cnpj
HELDER PASTI
Olha o que eu quero validar:  [<contato: (27) 999881254>] <type 'list'>
Veja o problema: entidade
Veja o problema: tipo_contato
Veja o problema: email
Subitem com problemas: (27) 999881254 {'entidade': [u'Este campo n\xe3o pode ser nulo.'], 'tipo_contato': [u"Valor u'CELULAR' n\xe3o \xe9 uma op\xe7\xe3o v\xe1lida."], 'email': [u'Formato Inv\xe1lido!']}
[<contato: (27) 999881254>]
Olha o que eu quero validar:  localizacao_simples object <class 'entidade.models.localizacao_simples'>
Olha o que eu quero validar:  [] <type 'list'>
Falha na validacao dos objetos: [ValidationError({'endereco': [u'A inst\xe2ncia de localizacao_simples com id 0 n\xe3o existe.'], 'cpf_cnpj': [u'Entidade com este Cnpj: j\xe1 existe.']}), ValidationError({'entidade': [u'Este campo n\xe3o pode ser nulo.'], 'tipo_contato': [u"Valor u'CELULAR' n\xe3o \xe9 uma op\xe7\xe3o v\xe1lida."], 'email': [u'Formato Inv\xe1lido!']}), ValidationError({'entidade': [u'Este campo n\xe3o pode ser nulo.'], 'tipo_contato': [u"Valor u'CELULAR' n\xe3o \xe9 uma op\xe7\xe3o v\xe1lida."], 'email': [u'Formato Inv\xe1lido!']})]
Internal Server Error: /entidade/visualizar/5/
Traceback (most recent call last):
  File "C:\Python27\lib\site-packages\django\core\handlers\base.py", line 158, in get_response
    % (callback.__module__, view_name))
ValueError: The view entidade.views.visualizar_entidade didn't return an HttpResponse object. It returned None instead.
Internal Server Error: /entidade/visualizar/5/
Traceback (most recent call last):
  File "C:\Python27\lib\site-packages\django\core\handlers\base.py", line 158, in get_response
    % (callback.__module__, view_name))
ValueError: The view entidade.views.visualizar_entidade didn't return an HttpResponse object. It returned None instead.
[21/Sep/2016 01:59:59] "POST /entidade/visualizar/5/ HTTP/1.1" 500 58089
Performing system checks...

System check identified no issues (0 silenced).
September 21, 2016 - 02:00:36
Django version 1.9.7, using settings 'sistema_contabil.settings'
Starting development server at http://localhost:8000/
Quit the server with CTRL-BREAK.
Olha o que eu quero validar:  HELDER PASTI <class 'entidade.models.entidade'>
Veja o problema: enderecoInternal Server Error: /entidade/visualizar/5/
Traceback (most recent call last):
  File "C:\Python27\lib\site-packages\django\core\handlers\base.py", line 149, in get_response
    response = self.process_exception_by_middleware(e, request)
  File "C:\Python27\lib\site-packages\django\core\handlers\base.py", line 147, in get_response
    response = wrapped_callback(request, *callback_args, **callback_kwargs)
  File "C:\Users\diego\OneDrive\Projetos\sistema_contabil\entidade\views.py", line 508, in visualizar_entidade
    validacao_dados,erros = validar_objetos_formulario(lista_objetos)
  File "C:\Users\diego\OneDrive\Projetos\sistema_contabil\entidade\views.py", line 648, in validar_objetos_formulario
    resultado, mensagem = validar_objeto(item)
  File "C:\Users\diego\OneDrive\Projetos\sistema_contabil\entidade\views.py", line 665, in validar_objeto
    print "Veja o problema:",item,excecao[item]
TypeError: sequence index must be integer, not 'str'
Internal Server Error: /entidade/visualizar/5/
Traceback (most recent call last):
  File "C:\Python27\lib\site-packages\django\core\handlers\base.py", line 149, in get_response
    response = self.process_exception_by_middleware(e, request)
  File "C:\Python27\lib\site-packages\django\core\handlers\base.py", line 147, in get_response
    response = wrapped_callback(request, *callback_args, **callback_kwargs)
  File "C:\Users\diego\OneDrive\Projetos\sistema_contabil\entidade\views.py", line 508, in visualizar_entidade
    validacao_dados,erros = validar_objetos_formulario(lista_objetos)
  File "C:\Users\diego\OneDrive\Projetos\sistema_contabil\entidade\views.py", line 648, in validar_objetos_formulario
    resultado, mensagem = validar_objeto(item)
  File "C:\Users\diego\OneDrive\Projetos\sistema_contabil\entidade\views.py", line 665, in validar_objeto
    print "Veja o problema:",item,excecao[item]
TypeError: sequence index must be integer, not 'str'
[21/Sep/2016 02:00:38] "POST /entidade/visualizar/5/ HTTP/1.1" 500 76523

Performing system checks...

System check identified no issues (0 silenced).
September 21, 2016 - 02:01:10
Django version 1.9.7, using settings 'sistema_contabil.settings'
Starting development server at http://localhost:8000/
Quit the server with CTRL-BREAK.
Olha o que eu quero validar:  HELDER PASTI <class 'entidade.models.entidade'>
Veja o problema: endereco
Veja o problema: cpf_cnpj
HELDER PASTI
Olha o que eu quero validar:  [<contato: (27) 999881254>] <type 'list'>
Veja o problema: entidade
Veja o problema: tipo_contato
Veja o problema: email
Subitem com problemas: (27) 999881254 {'entidade': [u'Este campo n\xe3o pode ser nulo.'], 'tipo_contato': [u"Valor u'CELULAR' n\xe3o \xe9 uma op\xe7\xe3o v\xe1lida."], 'email': [u'Formato Inv\xe1lido!']}
[<contato: (27) 999881254>]
Olha o que eu quero validar:  localizacao_simples object <class 'entidade.models.localizacao_simples'>
Olha o que eu quero validar:  [] <type 'list'>
Falha na validacao dos objetos: [ValidationError({'endereco': [u'A inst\xe2ncia de localizacao_simples com id 0 n\xe3o existe.'], 'cpf_cnpj': [u'Entidade com este Cnpj: j\xe1 existe.']}), ValidationError({'entidade': [u'Este campo n\xe3o pode ser nulo.'], 'tipo_contato': [u"Valor u'CELULAR' n\xe3o \xe9 uma op\xe7\xe3o v\xe1lida."], 'email': [u'Formato Inv\xe1lido!']}), ValidationError({'entidade': [u'Este campo n\xe3o pode ser nulo.'], 'tipo_contato': [u"Valor u'CELULAR' n\xe3o \xe9 uma op\xe7\xe3o v\xe1lida."], 'email': [u'Formato Inv\xe1lido!']})]
Internal Server Error: /entidade/visualizar/5/
Traceback (most recent call last):
  File "C:\Python27\lib\site-packages\django\core\handlers\base.py", line 158, in get_response
    % (callback.__module__, view_name))
ValueError: The view entidade.views.visualizar_entidade didn't return an HttpResponse object. It returned None instead.
Internal Server Error: /entidade/visualizar/5/
Traceback (most recent call last):
  File "C:\Python27\lib\site-packages\django\core\handlers\base.py", line 158, in get_response
    % (callback.__module__, view_name))
ValueError: The view entidade.views.visualizar_entidade didn't return an HttpResponse object. It returned None instead.
[21/Sep/2016 02:01:54] "POST /entidade/visualizar/5/ HTTP/1.1" 500 58089
Performing system checks...

System check identified no issues (0 silenced).
September 21, 2016 - 02:03:39
Django version 1.9.7, using settings 'sistema_contabil.settings'
Starting development server at http://localhost:8000/
Quit the server with CTRL-BREAK.
Olha o que eu quero validar:  HELDER PASTI <class 'entidade.models.entidade'>
Veja isso: [('endereco', [u'A inst\xe2ncia de localizacao_simples com id 0 n\xe3o existe.']), ('cpf_cnpj', [u'Entidade com este Cnpj: j\xe1 existe.'])]
Veja o problema: endereco
Veja o problema: cpf_cnpj
HELDER PASTI
Olha o que eu quero validar:  [<contato: (27) 999881254>] <type 'list'>
Veja isso: [('entidade', [u'Este campo n\xe3o pode ser nulo.']), ('tipo_contato', [u"Valor u'CELULAR' n\xe3o \xe9 uma op\xe7\xe3o v\xe1lida."]), ('email', [u'Formato Inv\xe1lido!'])]
Veja o problema: entidade
Veja o problema: tipo_contato
Veja o problema: email
Subitem com problemas: (27) 999881254 {'entidade': [u'Este campo n\xe3o pode ser nulo.'], 'tipo_contato': [u"Valor u'CELULAR' n\xe3o \xe9 uma op\xe7\xe3o v\xe1lida."], 'email': [u'Formato Inv\xe1lido!']}
[<contato: (27) 999881254>]
Olha o que eu quero validar:  localizacao_simples object <class 'entidade.models.localizacao_simples'>
Olha o que eu quero validar:  [] <type 'list'>
Falha na validacao dos objetos: [ValidationError({'endereco': [u'A inst\xe2ncia de localizacao_simples com id 0 n\xe3o existe.'], 'cpf_cnpj': [u'Entidade com este Cnpj: j\xe1 existe.']}), ValidationError({'entidade': [u'Este campo n\xe3o pode ser nulo.'], 'tipo_contato': [u"Valor u'CELULAR' n\xe3o \xe9 uma op\xe7\xe3o v\xe1lida."], 'email': [u'Formato Inv\xe1lido!']}), ValidationError({'entidade': [u'Este campo n\xe3o pode ser nulo.'], 'tipo_contato': [u"Valor u'CELULAR' n\xe3o \xe9 uma op\xe7\xe3o v\xe1lida."], 'email': [u'Formato Inv\xe1lido!']})]
Internal Server Error: /entidade/visualizar/5/
Traceback (most recent call last):
  File "C:\Python27\lib\site-packages\django\core\handlers\base.py", line 158, in get_response
    % (callback.__module__, view_name))
ValueError: The view entidade.views.visualizar_entidade didn't return an HttpResponse object. It returned None instead.
Internal Server Error: /entidade/visualizar/5/
Traceback (most recent call last):
  File "C:\Python27\lib\site-packages\django\core\handlers\base.py", line 158, in get_response
    % (callback.__module__, view_name))
ValueError: The view entidade.views.visualizar_entidade didn't return an HttpResponse object. It returned None instead.
[21/Sep/2016 02:03:43] "POST /entidade/visualizar/5/ HTTP/1.1" 500 58089
Performing system checks...

System check identified no issues (0 silenced).
September 21, 2016 - 02:04:34
Django version 1.9.7, using settings 'sistema_contabil.settings'
Starting development server at http://localhost:8000/
Quit the server with CTRL-BREAK.
Olha o que eu quero validar:  HELDER PASTI <class 'entidade.models.entidade'>
Veja o problema: ('endereco', [u'A inst\xe2ncia de localizacao_simples com id 0 n\xe3o existe.'])
Veja o problema: ('cpf_cnpj', [u'Entidade com este Cnpj: j\xe1 existe.'])
HELDER PASTI
Olha o que eu quero validar:  [<contato: (27) 999881254>] <type 'list'>
Veja o problema: ('entidade', [u'Este campo n\xe3o pode ser nulo.'])
Veja o problema: ('tipo_contato', [u"Valor u'CELULAR' n\xe3o \xe9 uma op\xe7\xe3o v\xe1lida."])
Veja o problema: ('email', [u'Formato Inv\xe1lido!'])
Subitem com problemas: (27) 999881254 {'entidade': [u'Este campo n\xe3o pode ser nulo.'], 'tipo_contato': [u"Valor u'CELULAR' n\xe3o \xe9 uma op\xe7\xe3o v\xe1lida."], 'email': [u'Formato Inv\xe1lido!']}
[<contato: (27) 999881254>]
Olha o que eu quero validar:  localizacao_simples object <class 'entidade.models.localizacao_simples'>
Olha o que eu quero validar:  [] <type 'list'>
Falha na validacao dos objetos: [ValidationError({'endereco': [u'A inst\xe2ncia de localizacao_simples com id 0 n\xe3o existe.'], 'cpf_cnpj': [u'Entidade com este Cnpj: j\xe1 existe.']}), ValidationError({'entidade': [u'Este campo n\xe3o pode ser nulo.'], 'tipo_contato': [u"Valor u'CELULAR' n\xe3o \xe9 uma op\xe7\xe3o v\xe1lida."], 'email': [u'Formato Inv\xe1lido!']}), ValidationError({'entidade': [u'Este campo n\xe3o pode ser nulo.'], 'tipo_contato': [u"Valor u'CELULAR' n\xe3o \xe9 uma op\xe7\xe3o v\xe1lida."], 'email': [u'Formato Inv\xe1lido!']})]
Internal Server Error: /entidade/visualizar/5/
Traceback (most recent call last):
  File "C:\Python27\lib\site-packages\django\core\handlers\base.py", line 158, in get_response
    % (callback.__module__, view_name))
ValueError: The view entidade.views.visualizar_entidade didn't return an HttpResponse object. It returned None instead.
Internal Server Error: /entidade/visualizar/5/
Traceback (most recent call last):
  File "C:\Python27\lib\site-packages\django\core\handlers\base.py", line 158, in get_response
    % (callback.__module__, view_name))
ValueError: The view entidade.views.visualizar_entidade didn't return an HttpResponse object. It returned None instead.
[21/Sep/2016 02:04:36] "POST /entidade/visualizar/5/ HTTP/1.1" 500 58089
Performing system checks...

System check identified no issues (0 silenced).
September 21, 2016 - 02:05:42
Django version 1.9.7, using settings 'sistema_contabil.settings'
Starting development server at http://localhost:8000/
Quit the server with CTRL-BREAK.
Olha o que eu quero validar:  HELDER PASTI <class 'entidade.models.entidade'>
HELDER PASTI
Olha o que eu quero validar:  [<contato: (27) 999881254>] <type 'list'>
Subitem com problemas: (27) 999881254 [('entidade', [u'Este campo n\xe3o pode ser nulo.']), ('tipo_contato', [u"Valor u'CELULAR' n\xe3o \xe9 uma op\xe7\xe3o v\xe1lida."]), ('email', [u'Formato Inv\xe1lido!'])]
[<contato: (27) 999881254>]
Olha o que eu quero validar:  localizacao_simples object <class 'entidade.models.localizacao_simples'>
Olha o que eu quero validar:  [] <type 'list'>
Falha na validacao dos objetos: [[('endereco', [u'A inst\xe2ncia de localizacao_simples com id 0 n\xe3o existe.']), ('cpf_cnpj', [u'Entidade com este Cnpj: j\xe1 existe.'])], ('entidade', [u'Este campo n\xe3o pode ser nulo.']), ('tipo_contato', [u"Valor u'CELULAR' n\xe3o \xe9 uma op\xe7\xe3o v\xe1lida."]), ('email', [u'Formato Inv\xe1lido!']), [('entidade', [u'Este campo n\xe3o pode ser nulo.']), ('tipo_contato', [u"Valor u'CELULAR' n\xe3o \xe9 uma op\xe7\xe3o v\xe1lida."]), ('email', [u'Formato Inv\xe1lido!'])]]
Internal Server Error: /entidade/visualizar/5/
Traceback (most recent call last):
  File "C:\Python27\lib\site-packages\django\core\handlers\base.py", line 158, in get_response
    % (callback.__module__, view_name))
ValueError: The view entidade.views.visualizar_entidade didn't return an HttpResponse object. It returned None instead.
Internal Server Error: /entidade/visualizar/5/
Traceback (most recent call last):
  File "C:\Python27\lib\site-packages\django\core\handlers\base.py", line 158, in get_response
    % (callback.__module__, view_name))
ValueError: The view entidade.views.visualizar_entidade didn't return an HttpResponse object. It returned None instead.
[21/Sep/2016 02:07:22] "POST /entidade/visualizar/5/ HTTP/1.1" 500 58089
Performing system checks...

System check identified no issues (0 silenced).
September 21, 2016 - 02:14:38
Django version 1.9.7, using settings 'sistema_contabil.settings'
Starting development server at http://localhost:8000/
Quit the server with CTRL-BREAK.
VALIDANDO A ENTIDADE: (False, [('endereco', [u'A inst\xe2ncia de localizacao_simples com id 0 n\xe3o existe.']), ('cpf_cnpj', [u'Entidade com este Cnpj: j\xe1 existe.'])])
Internal Server Error: /entidade/visualizar/5/
Traceback (most recent call last):
  File "C:\Python27\lib\site-packages\django\core\handlers\base.py", line 149, in get_response
    response = self.process_exception_by_middleware(e, request)
  File "C:\Python27\lib\site-packages\django\core\handlers\base.py", line 147, in get_response
    response = wrapped_callback(request, *callback_args, **callback_kwargs)
  File "C:\Users\diego\OneDrive\Projetos\sistema_contabil\entidade\views.py", line 509, in visualizar_entidade
    if validacao_dados:
NameError: global name 'validacao_dados' is not defined
Internal Server Error: /entidade/visualizar/5/
Traceback (most recent call last):
  File "C:\Python27\lib\site-packages\django\core\handlers\base.py", line 149, in get_response
    response = self.process_exception_by_middleware(e, request)
  File "C:\Python27\lib\site-packages\django\core\handlers\base.py", line 147, in get_response
    response = wrapped_callback(request, *callback_args, **callback_kwargs)
  File "C:\Users\diego\OneDrive\Projetos\sistema_contabil\entidade\views.py", line 509, in visualizar_entidade
    if validacao_dados:
NameError: global name 'validacao_dados' is not defined
[21/Sep/2016 02:14:40] "POST /entidade/visualizar/5/ HTTP/1.1" 500 68554
Performing system checks...

System check identified no issues (0 silenced).
September 21, 2016 - 02:15:09
Django version 1.9.7, using settings 'sistema_contabil.settings'
Starting development server at http://localhost:8000/
Quit the server with CTRL-BREAK.
VALIDANDO A ENTIDADE: (False, [('endereco', [u'A inst\xe2ncia de localizacao_simples com id 0 n\xe3o existe.']), ('cpf_cnpj', [u'Entidade com este Cnpj: j\xe1 existe.'])])
Internal Server Error: /entidade/visualizar/5/
Traceback (most recent call last):
  File "C:\Python27\lib\site-packages\django\core\handlers\base.py", line 158, in get_response
    % (callback.__module__, view_name))
ValueError: The view entidade.views.visualizar_entidade didn't return an HttpResponse object. It returned None instead.
Internal Server Error: /entidade/visualizar/5/
Traceback (most recent call last):
  File "C:\Python27\lib\site-packages\django\core\handlers\base.py", line 158, in get_response
    % (callback.__module__, view_name))
ValueError: The view entidade.views.visualizar_entidade didn't return an HttpResponse object. It returned None instead.
[21/Sep/2016 02:15:14] "POST /entidade/visualizar/5/ HTTP/1.1" 500 58089
Performing system checks...

System check identified no issues (0 silenced).
September 21, 2016 - 02:16:16
Django version 1.9.7, using settings 'sistema_contabil.settings'
Starting development server at http://localhost:8000/
Quit the server with CTRL-BREAK.
VALIDANDO A ENTIDADE: (False, [('endereco', [u'A inst\xe2ncia de localizacao_simples com id 0 n\xe3o existe.']), ('cpf_cnpj', [u'Entidade com este Cnpj: j\xe1 existe.'])])
VALIDANDO OS CONTATOS:Internal Server Error: /entidade/visualizar/5/
Traceback (most recent call last):
  File "C:\Python27\lib\site-packages\django\core\handlers\base.py", line 149, in get_response
    response = self.process_exception_by_middleware(e, request)
  File "C:\Python27\lib\site-packages\django\core\handlers\base.py", line 147, in get_response
    response = wrapped_callback(request, *callback_args, **callback_kwargs)
  File "C:\Users\diego\OneDrive\Projetos\sistema_contabil\entidade\views.py", line 506, in visualizar_entidade
    lista_objetos = construir_objetos_do_formulario(formulario)
  File "C:\Users\diego\OneDrive\Projetos\sistema_contabil\entidade\views.py", line 632, in construir_objetos_do_formulario
    print "VALIDANDO OS CONTATOS:", validar_objeto(registro_contato)
  File "C:\Users\diego\OneDrive\Projetos\sistema_contabil\entidade\views.py", line 663, in validar_objeto
    registro.full_clean()
AttributeError: 'list' object has no attribute 'full_clean'
Internal Server Error: /entidade/visualizar/5/
Traceback (most recent call last):
  File "C:\Python27\lib\site-packages\django\core\handlers\base.py", line 149, in get_response
    response = self.process_exception_by_middleware(e, request)
  File "C:\Python27\lib\site-packages\django\core\handlers\base.py", line 147, in get_response
    response = wrapped_callback(request, *callback_args, **callback_kwargs)
  File "C:\Users\diego\OneDrive\Projetos\sistema_contabil\entidade\views.py", line 506, in visualizar_entidade
    lista_objetos = construir_objetos_do_formulario(formulario)
  File "C:\Users\diego\OneDrive\Projetos\sistema_contabil\entidade\views.py", line 632, in construir_objetos_do_formulario
    print "VALIDANDO OS CONTATOS:", validar_objeto(registro_contato)
  File "C:\Users\diego\OneDrive\Projetos\sistema_contabil\entidade\views.py", line 663, in validar_objeto
    registro.full_clean()
AttributeError: 'list' object has no attribute 'full_clean'
[21/Sep/2016 02:16:24] "POST /entidade/visualizar/5/ HTTP/1.1" 500 76161

Performing system checks...

System check identified no issues (0 silenced).
September 21, 2016 - 02:16:58
Django version 1.9.7, using settings 'sistema_contabil.settings'
Starting development server at http://localhost:8000/
Quit the server with CTRL-BREAK.
VALIDANDO A ENTIDADE:Internal Server Error: /entidade/visualizar/5/
Traceback (most recent call last):
  File "C:\Python27\lib\site-packages\django\core\handlers\base.py", line 158, in get_response
    % (callback.__module__, view_name))
ValueError: The view entidade.views.visualizar_entidade didn't return an HttpResponse object. It returned None instead.
Internal Server Error: /entidade/visualizar/5/
Traceback (most recent call last):
  File "C:\Python27\lib\site-packages\django\core\handlers\base.py", line 158, in get_response
    % (callback.__module__, view_name))
ValueError: The view entidade.views.visualizar_entidade didn't return an HttpResponse object. It returned None instead.
 (False, [('endereco', [u'A inst\xe2ncia de localizacao_simples com id 0 n\xe3o existe.']), ('cpf_cnpj', [u'Entidade com este Cnpj: j\xe1 existe.'])])
VALIDANDO OS CONTATOS: (False, [('entidade', [u'Este campo n\xe3o pode ser nulo.']), ('tipo_contato', [u"Valor u'CELULAR' n\xe3o \xe9 uma op\xe7\xe3o v\xe1lida."]), ('email', [u'Formato Inv\xe1lido!'])])
[21/Sep/2016 02:17:00] "POST /entidade/visualizar/5/ HTTP/1.1" 500 58089
Performing system checks...

System check identified no issues (0 silenced).
September 21, 2016 - 02:18:06
Django version 1.9.7, using settings 'sistema_contabil.settings'
Starting development server at http://localhost:8000/
Quit the server with CTRL-BREAK.
VALIDANDO A ENTIDADE: (False, [('endereco', [u'A inst\xe2ncia de localizacao_simples com id 0 n\xe3o existe.']), ('cpf_cnpj', [u'Entidade com este Cnpj: j\xe1 existe.'])])
olha o id:Internal Server Error: /entidade/visualizar/5/
Traceback (most recent call last):
  File "C:\Python27\lib\site-packages\django\core\handlers\base.py", line 149, in get_response
    response = self.process_exception_by_middleware(e, request)
  File "C:\Python27\lib\site-packages\django\core\handlers\base.py", line 147, in get_response
    response = wrapped_callback(request, *callback_args, **callback_kwargs)
  File "C:\Users\diego\OneDrive\Projetos\sistema_contabil\entidade\views.py", line 506, in visualizar_entidade
    lista_objetos = construir_objetos_do_formulario(formulario)
  File "C:\Users\diego\OneDrive\Projetos\sistema_contabil\entidade\views.py", line 634, in construir_objetos_do_formulario
    print "olha o id:",item.entidade
  File "C:\Python27\lib\site-packages\django\db\models\fields\related_descriptors.py", line 179, in __get__
    "%s has no %s." % (self.field.model.__name__, self.field.name)
RelatedObjectDoesNotExist: contato has no entidade.
Internal Server Error: /entidade/visualizar/5/
Traceback (most recent call last):
  File "C:\Python27\lib\site-packages\django\core\handlers\base.py", line 149, in get_response
    response = self.process_exception_by_middleware(e, request)
  File "C:\Python27\lib\site-packages\django\core\handlers\base.py", line 147, in get_response
    response = wrapped_callback(request, *callback_args, **callback_kwargs)
  File "C:\Users\diego\OneDrive\Projetos\sistema_contabil\entidade\views.py", line 506, in visualizar_entidade
    lista_objetos = construir_objetos_do_formulario(formulario)
  File "C:\Users\diego\OneDrive\Projetos\sistema_contabil\entidade\views.py", line 634, in construir_objetos_do_formulario
    print "olha o id:",item.entidade
  File "C:\Python27\lib\site-packages\django\db\models\fields\related_descriptors.py", line 179, in __get__
    "%s has no %s." % (self.field.model.__name__, self.field.name)
RelatedObjectDoesNotExist: contato has no entidade.
[21/Sep/2016 02:18:09] "POST /entidade/visualizar/5/ HTTP/1.1" 500 77308

Performing system checks...

System check identified no issues (0 silenced).
September 21, 2016 - 02:18:21
Django version 1.9.7, using settings 'sistema_contabil.settings'
Starting development server at http://localhost:8000/
Quit the server with CTRL-BREAK.
VALIDANDO A ENTIDADE: (False, [('endereco', [u'A inst\xe2ncia de localizacao_simples com id 0 n\xe3o existe.']), ('cpf_cnpj', [u'Entidade com este Cnpj: j\xe1 existe.'])])
olha o id: None
VALIDANDO OS CONTATOS: (False, [('entidade', [u'Este campo n\xe3o pode ser nulo.']), ('tipo_contato', [u"Valor u'CELULAR' n\xe3o \xe9 uma op\xe7\xe3o v\xe1lida."]), ('email', [u'Formato Inv\xe1lido!'])])
Internal Server Error: /entidade/visualizar/5/
Traceback (most recent call last):
  File "C:\Python27\lib\site-packages\django\core\handlers\base.py", line 158, in get_response
    % (callback.__module__, view_name))
ValueError: The view entidade.views.visualizar_entidade didn't return an HttpResponse object. It returned None instead.
Internal Server Error: /entidade/visualizar/5/
Traceback (most recent call last):
  File "C:\Python27\lib\site-packages\django\core\handlers\base.py", line 158, in get_response
    % (callback.__module__, view_name))
ValueError: The view entidade.views.visualizar_entidade didn't return an HttpResponse object. It returned None instead.
[21/Sep/2016 02:18:23] "POST /entidade/visualizar/5/ HTTP/1.1" 500 58089
Performing system checks...

System check identified no issues (0 silenced).
September 21, 2016 - 02:21:02
Django version 1.9.7, using settings 'sistema_contabil.settings'
Starting development server at http://localhost:8000/
Quit the server with CTRL-BREAK.
VALIDANDO A ENTIDADE: (False, [('endereco', [u'A inst\xe2ncia de localizacao_simples com id 0 n\xe3o existe.']), ('cpf_cnpj', [u'Entidade com este Cnpj: j\xe1 existe.'])])
olha o id: None
VALIDANDO OS CONTATOS: (False, [('entidade', [u'Este campo n\xe3o pode ser nulo.']), ('tipo_contato', [u'Certifique-se de que o valor tenha no m\xe1ximo 1 caractere (ele possui 7).']), ('email', [u'Formato Inv\xe1lido!'])])
Internal Server Error: /entidade/visualizar/5/
Traceback (most recent call last):
  File "C:\Python27\lib\site-packages\django\core\handlers\base.py", line 158, in get_response
    % (callback.__module__, view_name))
ValueError: The view entidade.views.visualizar_entidade didn't return an HttpResponse object. It returned None instead.
Internal Server Error: /entidade/visualizar/5/
Traceback (most recent call last):
  File "C:\Python27\lib\site-packages\django\core\handlers\base.py", line 158, in get_response
    % (callback.__module__, view_name))
ValueError: The view entidade.views.visualizar_entidade didn't return an HttpResponse object. It returned None instead.
[21/Sep/2016 02:21:05] "POST /entidade/visualizar/5/ HTTP/1.1" 500 58089
Performing system checks...

System check identified no issues (0 silenced).
September 21, 2016 - 02:21:44
Django version 1.9.7, using settings 'sistema_contabil.settings'
Starting development server at http://localhost:8000/
Quit the server with CTRL-BREAK.
VALIDANDO A ENTIDADE: (False, [('endereco', [u'A inst\xe2ncia de localizacao_simples com id 0 n\xe3o existe.']), ('cpf_cnpj', [u'Entidade com este Cnpj: j\xe1 existe.'])])
olha o id: None
VALIDANDO OS CONTATOS: (False, [('entidade', [u'Este campo n\xe3o pode ser nulo.']), ('email', [u'Formato Inv\xe1lido!'])])
Internal Server Error: /entidade/visualizar/5/
Traceback (most recent call last):
  File "C:\Python27\lib\site-packages\django\core\handlers\base.py", line 158, in get_response
    % (callback.__module__, view_name))
ValueError: The view entidade.views.visualizar_entidade didn't return an HttpResponse object. It returned None instead.
Internal Server Error: /entidade/visualizar/5/
Traceback (most recent call last):
  File "C:\Python27\lib\site-packages\django\core\handlers\base.py", line 158, in get_response
    % (callback.__module__, view_name))
ValueError: The view entidade.views.visualizar_entidade didn't return an HttpResponse object. It returned None instead.
[21/Sep/2016 02:22:04] "POST /entidade/visualizar/5/ HTTP/1.1" 500 58089
Performing system checks...

System check identified no issues (0 silenced).
September 21, 2016 - 02:22:42
Django version 1.9.7, using settings 'sistema_contabil.settings'
Starting development server at http://localhost:8000/
Quit the server with CTRL-BREAK.
VALIDANDO A ENTIDADE: (False, [('endereco', [u'A inst\xe2ncia de localizacao_simples com id 0 n\xe3o existe.']), ('cpf_cnpj', [u'Entidade com este Cnpj: j\xe1 existe.'])])
olha o id: None
olha o email: PARTICULAR
VALIDANDO OS CONTATOS: (False, [('entidade', [u'Este campo n\xe3o pode ser nulo.']), ('email', [u'Formato Inv\xe1lido!'])])
Internal Server Error: /entidade/visualizar/5/
Traceback (most recent call last):
  File "C:\Python27\lib\site-packages\django\core\handlers\base.py", line 158, in get_response
    % (callback.__module__, view_name))
ValueError: The view entidade.views.visualizar_entidade didn't return an HttpResponse object. It returned None instead.
Internal Server Error: /entidade/visualizar/5/
Traceback (most recent call last):
  File "C:\Python27\lib\site-packages\django\core\handlers\base.py", line 158, in get_response
    % (callback.__module__, view_name))
ValueError: The view entidade.views.visualizar_entidade didn't return an HttpResponse object. It returned None instead.
[21/Sep/2016 02:22:45] "POST /entidade/visualizar/5/ HTTP/1.1" 500 58089
Performing system checks...

System check identified no issues (0 silenced).
September 21, 2016 - 02:23:56
Django version 1.9.7, using settings 'sistema_contabil.settings'
Starting development server at http://localhost:8000/
Quit the server with CTRL-BREAK.
VALIDANDO A ENTIDADE: (False, [('endereco', [u'A inst\xe2ncia de localizacao_simples com id 0 n\xe3o existe.']), ('cpf_cnpj', [u'Entidade com este Cnpj: j\xe1 existe.'])])
OLHA OS CAMPOS NA HORA DE CONSTRUIR O CONTATO: [u'CELULAR', u'(27) 999881254', u'HELDER PASTI', u'PARTICULAR', u'helder@pcns.com.br']
olha o id: None
olha o email: PARTICULAR
VALIDANDO OS CONTATOS: (False, [('entidade', [u'Este campo n\xe3o pode ser nulo.']), ('email', [u'Formato Inv\xe1lido!'])])
Internal Server Error: /entidade/visualizar/5/
Traceback (most recent call last):
  File "C:\Python27\lib\site-packages\django\core\handlers\base.py", line 158, in get_response
    % (callback.__module__, view_name))
ValueError: The view entidade.views.visualizar_entidade didn't return an HttpResponse object. It returned None instead.
Internal Server Error: /entidade/visualizar/5/
Traceback (most recent call last):
  File "C:\Python27\lib\site-packages\django\core\handlers\base.py", line 158, in get_response
    % (callback.__module__, view_name))
ValueError: The view entidade.views.visualizar_entidade didn't return an HttpResponse object. It returned None instead.
[21/Sep/2016 02:23:57] "POST /entidade/visualizar/5/ HTTP/1.1" 500 58089
Performing system checks...

System check identified no issues (0 silenced).
September 21, 2016 - 02:25:04
Django version 1.9.7, using settings 'sistema_contabil.settings'
Starting development server at http://localhost:8000/
Quit the server with CTRL-BREAK.
VALIDANDO A ENTIDADE: (False, [('endereco', [u'A inst\xe2ncia de localizacao_simples com id 0 n\xe3o existe.']), ('cpf_cnpj', [u'Entidade com este Cnpj: j\xe1 existe.'])])
OLHA OS CAMPOS NA HORA DE CONSTRUIR O CONTATO: [u'CELULAR', u'(27) 999881254', u'HELDER PASTI', u'PARTICULAR', u'helder@pcns.com.br']
olha o id: None
olha o email: helder@pcns.com.br
VALIDANDO OS CONTATOS: (False, [('entidade', [u'Este campo n\xe3o pode ser nulo.'])])
Internal Server Error: /entidade/visualizar/5/
Traceback (most recent call last):
  File "C:\Python27\lib\site-packages\django\core\handlers\base.py", line 158, in get_response
    % (callback.__module__, view_name))
ValueError: The view entidade.views.visualizar_entidade didn't return an HttpResponse object. It returned None instead.
Internal Server Error: /entidade/visualizar/5/
Traceback (most recent call last):
  File "C:\Python27\lib\site-packages\django\core\handlers\base.py", line 158, in get_response
    % (callback.__module__, view_name))
ValueError: The view entidade.views.visualizar_entidade didn't return an HttpResponse object. It returned None instead.
[21/Sep/2016 02:25:06] "POST /entidade/visualizar/5/ HTTP/1.1" 500 58089
Performing system checks...

System check identified no issues (0 silenced).
September 21, 2016 - 02:25:27
Django version 1.9.7, using settings 'sistema_contabil.settings'
Starting development server at http://localhost:8000/
Quit the server with CTRL-BREAK.
VALIDANDO A LOCALIZACAO: (True, '')
VALIDANDO A ENTIDADE: (False, [('endereco', [u'A inst\xe2ncia de localizacao_simples com id 0 n\xe3o existe.']), ('cpf_cnpj', [u'Entidade com este Cnpj: j\xe1 existe.'])])
VALIDANDO OS CONTATOS: (False, [('entidade', [u'Este campo n\xe3o pode ser nulo.'])])
Internal Server Error: /entidade/visualizar/5/
Traceback (most recent call last):
  File "C:\Python27\lib\site-packages\django\core\handlers\base.py", line 158, in get_response
    % (callback.__module__, view_name))
ValueError: The view entidade.views.visualizar_entidade didn't return an HttpResponse object. It returned None instead.
Internal Server Error: /entidade/visualizar/5/
Traceback (most recent call last):
  File "C:\Python27\lib\site-packages\django\core\handlers\base.py", line 158, in get_response
    % (callback.__module__, view_name))
ValueError: The view entidade.views.visualizar_entidade didn't return an HttpResponse object. It returned None instead.
[21/Sep/2016 02:28:27] "POST /entidade/visualizar/5/ HTTP/1.1" 500 58089
Performing system checks...

System check identified no issues (0 silenced).
September 21, 2016 - 02:30:18
Django version 1.9.7, using settings 'sistema_contabil.settings'
Starting development server at http://localhost:8000/
Quit the server with CTRL-BREAK.
VALIDANDO A LOCALIZACAO: (True, '')
VALIDANDO A ENTIDADE: (False, [('endereco', [u'A inst\xe2ncia de localizacao_simples com id 0 n\xe3o existe.']), ('cpf_cnpj', [u'Entidade com este Cnpj: j\xe1 existe.'])])
VALIDANDO OS CONTATOS: (False, [('entidade', [u'Este campo n\xe3o pode ser nulo.'])])
Internal Server Error: /entidade/visualizar/5/
Traceback (most recent call last):
  File "C:\Python27\lib\site-packages\django\core\handlers\base.py", line 158, in get_response
    % (callback.__module__, view_name))
ValueError: The view entidade.views.visualizar_entidade didn't return an HttpResponse object. It returned None instead.
Internal Server Error: /entidade/visualizar/5/
Traceback (most recent call last):
  File "C:\Python27\lib\site-packages\django\core\handlers\base.py", line 158, in get_response
    % (callback.__module__, view_name))
ValueError: The view entidade.views.visualizar_entidade didn't return an HttpResponse object. It returned None instead.
[21/Sep/2016 02:30:23] "POST /entidade/visualizar/5/ HTTP/1.1" 500 58089
Performing system checks...

System check identified no issues (0 silenced).
September 21, 2016 - 02:34:13
Django version 1.9.7, using settings 'sistema_contabil.settings'
Starting development server at http://localhost:8000/
Quit the server with CTRL-BREAK.
Performing system checks...

System check identified no issues (0 silenced).
September 21, 2016 - 02:45:46
Django version 1.9.7, using settings 'sistema_contabil.settings'
Starting development server at http://localhost:8000/
Quit the server with CTRL-BREAK.
Performing system checks...

System check identified no issues (0 silenced).
September 21, 2016 - 02:45:53
Django version 1.9.7, using settings 'sistema_contabil.settings'
Starting development server at http://localhost:8000/
Quit the server with CTRL-BREAK.
Performing system checks...

System check identified no issues (0 silenced).
September 21, 2016 - 02:49:36
Django version 1.9.7, using settings 'sistema_contabil.settings'
Starting development server at http://localhost:8000/
Quit the server with CTRL-BREAK.
Internal Server Error: /entidade/visualizar/5/
Traceback (most recent call last):
  File "C:\Python27\lib\site-packages\django\core\handlers\base.py", line 149, in get_response
    response = self.process_exception_by_middleware(e, request)
  File "C:\Python27\lib\site-packages\django\core\handlers\base.py", line 147, in get_response
    response = wrapped_callback(request, *callback_args, **callback_kwargs)
  File "C:\Users\diego\OneDrive\Projetos\sistema_contabil\entidade\views.py", line 512, in visualizar_entidade
    lista_objetos = load_objects_from_form(formulario,cliente,cliente.endereco,meus_contatos,minhas_atividades)
  File "C:\Users\diego\OneDrive\Projetos\sistema_contabil\entidade\views.py", line 633, in load_objects_from_form
    registro_entidade = formulario.get_entidade(formulario)
TypeError: get_object_entidade() takes exactly 3 arguments (2 given)
Internal Server Error: /entidade/visualizar/5/
Traceback (most recent call last):
  File "C:\Python27\lib\site-packages\django\core\handlers\base.py", line 149, in get_response
    response = self.process_exception_by_middleware(e, request)
  File "C:\Python27\lib\site-packages\django\core\handlers\base.py", line 147, in get_response
    response = wrapped_callback(request, *callback_args, **callback_kwargs)
  File "C:\Users\diego\OneDrive\Projetos\sistema_contabil\entidade\views.py", line 512, in visualizar_entidade
    lista_objetos = load_objects_from_form(formulario,cliente,cliente.endereco,meus_contatos,minhas_atividades)
  File "C:\Users\diego\OneDrive\Projetos\sistema_contabil\entidade\views.py", line 633, in load_objects_from_form
    registro_entidade = formulario.get_entidade(formulario)
TypeError: get_object_entidade() takes exactly 3 arguments (2 given)
[21/Sep/2016 02:49:50] "POST /entidade/visualizar/5/ HTTP/1.1" 500 74373
Performing system checks...

System check identified no issues (0 silenced).
September 21, 2016 - 02:50:19
Django version 1.9.7, using settings 'sistema_contabil.settings'
Starting development server at http://localhost:8000/
Quit the server with CTRL-BREAK.
carregando..
VALIDANDO A ENTIDADE:Internal Server Error: /entidade/visualizar/5/
Traceback (most recent call last):
  File "C:\Python27\lib\site-packages\django\core\handlers\base.py", line 158, in get_response
    % (callback.__module__, view_name))
ValueError: The view entidade.views.visualizar_entidade didn't return an HttpResponse object. It returned None instead.
Internal Server Error: /entidade/visualizar/5/
Traceback (most recent call last):
  File "C:\Python27\lib\site-packages\django\core\handlers\base.py", line 158, in get_response
    % (callback.__module__, view_name))
ValueError: The view entidade.views.visualizar_entidade didn't return an HttpResponse object. It returned None instead.
 (True, '')
[21/Sep/2016 02:50:22] "POST /entidade/visualizar/5/ HTTP/1.1" 500 58089
Performing system checks...

System check identified no issues (0 silenced).
September 21, 2016 - 02:51:48
Django version 1.9.7, using settings 'sistema_contabil.settings'
Starting development server at http://localhost:8000/
Quit the server with CTRL-BREAK.
Performing system checks...

System check identified no issues (0 silenced).
September 21, 2016 - 02:52:33
Django version 1.9.7, using settings 'sistema_contabil.settings'
Starting development server at http://localhost:8000/
Quit the server with CTRL-BREAK.
Performing system checks...

System check identified no issues (0 silenced).
September 21, 2016 - 02:53:09
Django version 1.9.7, using settings 'sistema_contabil.settings'
Starting development server at http://localhost:8000/
Quit the server with CTRL-BREAK.
Performing system checks...

System check identified no issues (0 silenced).
September 21, 2016 - 02:53:17
Django version 1.9.7, using settings 'sistema_contabil.settings'
Starting development server at http://localhost:8000/
Quit the server with CTRL-BREAK.
carregando..
VALIDANDO A LOCALIZACAO: (True, '')
carregando..
VALIDANDO A ENTIDADE:Internal Server Error: /entidade/visualizar/5/
Traceback (most recent call last):
  File "C:\Python27\lib\site-packages\django\core\handlers\base.py", line 158, in get_response
    % (callback.__module__, view_name))
ValueError: The view entidade.views.visualizar_entidade didn't return an HttpResponse object. It returned None instead.
Internal Server Error: /entidade/visualizar/5/
Traceback (most recent call last):
  File "C:\Python27\lib\site-packages\django\core\handlers\base.py", line 158, in get_response
    % (callback.__module__, view_name))
ValueError: The view entidade.views.visualizar_entidade didn't return an HttpResponse object. It returned None instead.
 (True, '')
[21/Sep/2016 02:53:33] "POST /entidade/visualizar/5/ HTTP/1.1" 500 58089
Performing system checks...

System check identified no issues (0 silenced).
September 21, 2016 - 02:55:15
Django version 1.9.7, using settings 'sistema_contabil.settings'
Starting development server at http://localhost:8000/
Quit the server with CTRL-BREAK.
[21/Sep/2016 03:18:22] "POST /entidade/visualizar/5/ HTTP/1.1" 500 58089
Traceback (most recent call last):
  File "C:/Users/diego/OneDrive/Projetos/sistema_contabil/manage.py", line 10, in <module>
    execute_from_command_line(sys.argv)
  File "C:\Python27\lib\site-packages\django\core\management\__init__.py", line 353, in execute_from_command_line
    utility.execute()


Process finished with exit code 0
